Workbook
Name MAP_TABLE: 内部_リスト!$C$2:$D$20
Name RESPX_001: 内部_リスト!$F$2:$F$4
Name RESPX_002: 内部_リスト!$G$2:$G$5
Name RESPX_003: 内部_リスト!$H$2:$H$5
Name RESPX_004: 内部_リスト!$I$2:$I$4
Name RESPX_005: 内部_リスト!$J$2:$J$3
Name RESPX_006: 内部_リスト!$K$2:$K$3
Name RESPX_007: 内部_リスト!$L$2:$L$3
Name RESPX_008: 内部_リスト!$M$2:$M$5
Name RESPX_009: 内部_リスト!$N$2:$N$3
Name RESPX_010: 内部_リスト!$O$2:$O$3
Name RESPX_011: 内部_リスト!$P$2:$P$5
Name RESPX_012: 内部_リスト!$Q$2:$Q$3
Name RESPX_013: 内部_リスト!$R$2:$R$3
Name RESPX_014: 内部_リスト!$S$2:$S$3
Name RESPX_015: 内部_リスト!$T$2:$T$2
Name RESPX_016: 内部_リスト!$U$2:$U$3
Name RESPX_017: 内部_リスト!$V$2:$V$2
Name RESPX_018: 内部_リスト!$W$2:$W$2
Name RESPX_019: 内部_リスト!$X$2:$X$2
Name STAGE_LIST: 内部_リスト!$A$2:$A$20
Name STATUS_LIST: 内部_リスト!$B$2:$B$9

Sheet 架電シート
A1: No | B1: 施設名 | C1: 電話番号 | D1: エリア | E1: 担当部署/役職 | F1: 担当者名 | G1: 現在ステージ（選択） | H1: 相手の反応（選択） | I1: 次に話す内容（自動表示） | J1: 次ステージ（自動） | K1: 結果ステータス | L1: 次回架電日時 | M1: メモ | N1: 送付先メール | O1: 最終更新 | R1: ステージ2（選択/自動） | S1: 反応2（選択） | T1: 話す内容2（自動表示） | U1: 次ステージ2（自動） | V1: ステージ3（選択/自動） | W1: 反応3（選択） | X1: 話す内容3（自動表示） | Y1: 次ステージ3（自動） | Z1: ステージ4（選択/自動） | AA1: 反応4（選択） | AB1: 話す内容4（自動表示） | AC1: 次ステージ4（自動） | AD1: ステージ5（選択/自動） | AE1: 反応5（選択） | AF1: 話す内容5（自動表示） | AG1: 次ステージ5（自動）
A2: 1 | B2: 別府温泉 杉乃井ホテル | C2: 0977-78-8888 | D2: 観海寺 | G2: ①架電 | H2: 担当者に直接繋がった | I2: =SUBSTITUTE(SUBSTITUTE(SUBSTITUTE(SUBSTITUTE(SUBSTITUTE(SUBSTITUTE(SUBSTITUTE(SUBSTITUTE(SUBSTITUTE(SUBSTITUTE(SUBSTITUTE(Q2,"{会社}",設定!$B$3),"{自分}",設定!$B$4),"{サービス}",設定!$B$5),"{料金}",設定!$B$7),"{日付1}",設定!$B$8),"{日付2}",設定!$B$9),"{時間1}",設定!$B$10),"{時間2}",設定!$B$11),"{時間}","（指定時間）"),"{日付確定}","（確定日）"),"{時間確定}","（確定時間）") -> （担当者様へ）お世話になっております。株式会社NanoActのキンタマと申します。宿泊者さま向けに「特定小型原付のシェアリング」を施設に設置するご相談でお電話しました。今1〜2分だけお時間よろしいでしょうか？ | J2: =IFERROR(VLOOKUP(P2,スクリプト_フロー!$A:$F,4,FALSE),"") -> ⑥目的伝達 | K2: 未架電 | P2: =G2&"|"&H2 -> ①架電|担当者に直接繋がった | Q2: =IFERROR(VLOOKUP(P2,スクリプト_フロー!$A:$F,5,FALSE),"") -> （担当者様へ）お世話になっております。{会社}の{自分}と申します。宿泊者さま向けに「{サービス}」を施設に設置するご相談でお電話しました。今1〜2分だけお時間よろしいでしょうか？ | T2: =IF(DA2="","",SUBSTITUTE(SUBSTITUTE(SUBSTITUTE(SUBSTITUTE(SUBSTITUTE(SUBSTITUTE(SUBSTITUTE(SUBSTITUTE(SUBSTITUTE(SUBSTITUTE(SUBSTITUTE(DA2,"{会社}",設定!$B$3),"{自分}",設定!$B$4),"{サービス}",設定!$B$5),"{料金}",設定!$B$7),"{日付1}",設定!$B$8),"{日付2}",設定!$B$9),"{時間1}",設定!$B$10),"{時間2}",設定!$B$11),"{時間}","（指定時間）"),"{日付確定}","（確定日）"),"{時間確定}","（確定時間）")) | U2: =IFERROR(VLOOKUP(CZ2,スクリプト_フロー!$A:$F,4,FALSE),"") | V2: =IF(U2="","",U2) | X2: =IF(DC2="","",SUBSTITUTE(SUBSTITUTE(SUBSTITUTE(SUBSTITUTE(SUBSTITUTE(SUBSTITUTE(SUBSTITUTE(SUBSTITUTE(SUBSTITUTE(SUBSTITUTE(SUBSTITUTE(DC2,"{会社}",設定!$B$3),"{自分}",設定!$B$4),"{サービス}",設定!$B$5),"{料金}",設定!$B$7),"{日付1}",設定!$B$8),"{日付2}",設定!$B$9),"{時間1}",設定!$B$10),"{時間2}",設定!$B$11),"{時間}","（指定時間）"),"{日付確定}","（確定日）"),"{時間確定}","（確定時間）")) | Y2: =IFERROR(VLOOKUP(DB2,スクリプト_フロー!$A:$F,4,FALSE),"") | Z2: =IF(Y2="","",Y2) | AA2: ①架電 | AB2: =IF(DE2="","",SUBSTITUTE(SUBSTITUTE(SUBSTITUTE(SUBSTITUTE(SUBSTITUTE(SUBSTITUTE(SUBSTITUTE(SUBSTITUTE(SUBSTITUTE(SUBSTITUTE(SUBSTITUTE(DE2,"{会社}",設定!$B$3),"{自分}",設定!$B$4),"{サービス}",設定!$B$5),"{料金}",設定!$B$7),"{日付1}",設定!$B$8),"{日付2}",設定!$B$9),"{時間1}",設定!$B$10),"{時間2}",設定!$B$11),"{時間}","（指定時間）"),"{日付確定}","（確定日）"),"{時間確定}","（確定時間）")) | AC2: =IFERROR(VLOOKUP(DD2,スクリプト_フロー!$A:$F,4,FALSE),"") | AD2: =IF(AC2="","",AC2) | AE2: RESPX_001 | AF2: =IF(DG2="","",SUBSTITUTE(SUBSTITUTE(SUBSTITUTE(SUBSTITUTE(SUBSTITUTE(SUBSTITUTE(SUBSTITUTE(SUBSTITUTE(SUBSTITUTE(SUBSTITUTE(SUBSTITUTE(DG2,"{会社}",設定!$B$3),"{自分}",設定!$B$4),"{サービス}",設定!$B$5),"{料金}",設定!$B$7),"{日付1}",設定!$B$8),"{日付2}",設定!$B$9),"{時間1}",設定!$B$10),"{時間2}",設定!$B$11),"{時間}","（指定時間）"),"{日付確定}","（確定日）"),"{時間確定}","（確定時間）")) | AG2: =IFERROR(VLOOKUP(DF2,スクリプト_フロー!$A:$F,4,FALSE),"") | CZ2: =R2&"|"&S2 -> | | DA2: =IFERROR(VLOOKUP(CZ2,スクリプト_フロー!$A:$F,5,FALSE),"") | DB2: =V2&"|"&W2 -> | | DC2: =IFERROR(VLOOKUP(DB2,スクリプト_フロー!$A:$F,5,FALSE),"") | DD2: =Z2&"|"&AA2 -> |①架電 | DE2: =IFERROR(VLOOKUP(DD2,スクリプト_フロー!$A:$F,5,FALSE),"") | DF2: =AD2&"|"&AE2 -> |RESPX_001 | DG2: =IFERROR(VLOOKUP(DF2,スクリプト_フロー!$A:$F,5,FALSE),"")
A3: 2 | B3: 界 別府 | C3: 050-3134-8092 | D3: 北浜 | G3: ①架電 | I3: =SUBSTITUTE(SUBSTITUTE(SUBSTITUTE(SUBSTITUTE(SUBSTITUTE(SUBSTITUTE(SUBSTITUTE(SUBSTITUTE(SUBSTITUTE(SUBSTITUTE(SUBSTITUTE(Q3,"{会社}",設定!$B$3),"{自分}",設定!$B$4),"{サービス}",設定!$B$5),"{料金}",設定!$B$7),"{日付1}",設定!$B$8),"{日付2}",設定!$B$9),"{時間1}",設定!$B$10),"{時間2}",設定!$B$11),"{時間}","（指定時間）"),"{日付確定}","（確定日）"),"{時間確定}","（確定時間）") | J3: =IFERROR(VLOOKUP(P3,スクリプト_フロー!$A:$F,4,FALSE),"") | K3: 未架電 | P3: =G3&"|"&H3 -> ①架電| | Q3: =IFERROR(VLOOKUP(P3,スクリプト_フロー!$A:$F,5,FALSE),"") | R3: =IF(J3="","",J3) | T3: =IF(DA3="","",SUBSTITUTE(SUBSTITUTE(SUBSTITUTE(SUBSTITUTE(SUBSTITUTE(SUBSTITUTE(SUBSTITUTE(SUBSTITUTE(SUBSTITUTE(SUBSTITUTE(SUBSTITUTE(DA3,"{会社}",設定!$B$3),"{自分}",設定!$B$4),"{サービス}",設定!$B$5),"{料金}",設定!$B$7),"{日付1}",設定!$B$8),"{日付2}",設定!$B$9),"{時間1}",設定!$B$10),"{時間2}",設定!$B$11),"{時間}","（指定時間）"),"{日付確定}","（確定日）"),"{時間確定}","（確定時間）")) | U3: =IFERROR(VLOOKUP(CZ3,スクリプト_フロー!$A:$F,4,FALSE),"") | V3: =IF(U3="","",U3) | X3: =IF(DC3="","",SUBSTITUTE(SUBSTITUTE(SUBSTITUTE(SUBSTITUTE(SUBSTITUTE(SUBSTITUTE(SUBSTITUTE(SUBSTITUTE(SUBSTITUTE(SUBSTITUTE(SUBSTITUTE(DC3,"{会社}",設定!$B$3),"{自分}",設定!$B$4),"{サービス}",設定!$B$5),"{料金}",設定!$B$7),"{日付1}",設定!$B$8),"{日付2}",設定!$B$9),"{時間1}",設定!$B$10),"{時間2}",設定!$B$11),"{時間}","（指定時間）"),"{日付確定}","（確定日）"),"{時間確定}","（確定時間）")) | Y3: =IFERROR(VLOOKUP(DB3,スクリプト_フロー!$A:$F,4,FALSE),"") | Z3: =IF(Y3="","",Y3) | AA3: ①-2自動音声 | AB3: =IF(DE3="","",SUBSTITUTE(SUBSTITUTE(SUBSTITUTE(SUBSTITUTE(SUBSTITUTE(SUBSTITUTE(SUBSTITUTE(SUBSTITUTE(SUBSTITUTE(SUBSTITUTE(SUBSTITUTE(DE3,"{会社}",設定!$B$3),"{自分}",設定!$B$4),"{サービス}",設定!$B$5),"{料金}",設定!$B$7),"{日付1}",設定!$B$8),"{日付2}",設定!$B$9),"{時間1}",設定!$B$10),"{時間2}",設定!$B$11),"{時間}","（指定時間）"),"{日付確定}","（確定日）"),"{時間確定}","（確定時間）")) | AC3: =IFERROR(VLOOKUP(DD3,スクリプト_フロー!$A:$F,4,FALSE),"") | AD3: =IF(AC3="","",AC3) | AE3: RESPX_002 | AF3: =IF(DG3="","",SUBSTITUTE(SUBSTITUTE(SUBSTITUTE(SUBSTITUTE(SUBSTITUTE(SUBSTITUTE(SUBSTITUTE(SUBSTITUTE(SUBSTITUTE(SUBSTITUTE(SUBSTITUTE(DG3,"{会社}",設定!$B$3),"{自分}",設定!$B$4),"{サービス}",設定!$B$5),"{料金}",設定!$B$7),"{日付1}",設定!$B$8),"{日付2}",設定!$B$9),"{時間1}",設定!$B$10),"{時間2}",設定!$B$11),"{時間}","（指定時間）"),"{日付確定}","（確定日）"),"{時間確定}","（確定時間）")) | AG3: =IFERROR(VLOOKUP(DF3,スクリプト_フロー!$A:$F,4,FALSE),"") | CZ3: =R3&"|"&S3 -> | | DA3: =IFERROR(VLOOKUP(CZ3,スクリプト_フロー!$A:$F,5,FALSE),"") | DB3: =V3&"|"&W3 -> | | DC3: =IFERROR(VLOOKUP(DB3,スクリプト_フロー!$A:$F,5,FALSE),"") | DD3: =Z3&"|"&AA3 -> |①-2自動音声 | DE3: =IFERROR(VLOOKUP(DD3,スクリプト_フロー!$A:$F,5,FALSE),"") | DF3: =AD3&"|"&AE3 -> |RESPX_002 | DG3: =IFERROR(VLOOKUP(DF3,スクリプト_フロー!$A:$F,5,FALSE),"")
A4: 3 | B4: 亀の井ホテル 別府 | C4: 0977-22-3301 | D4: 別府駅周辺 | G4: ①架電 | I4: =SUBSTITUTE(SUBSTITUTE(SUBSTITUTE(SUBSTITUTE(SUBSTITUTE(SUBSTITUTE(SUBSTITUTE(SUBSTITUTE(SUBSTITUTE(SUBSTITUTE(SUBSTITUTE(Q4,"{会社}",設定!$B$3),"{自分}",設定!$B$4),"{サービス}",設定!$B$5),"{料金}",設定!$B$7),"{日付1}",設定!$B$8),"{日付2}",設定!$B$9),"{時間1}",設定!$B$10),"{時間2}",設定!$B$11),"{時間}","（指定時間）"),"{日付確定}","（確定日）"),"{時間確定}","（確定時間）") | J4: =IFERROR(VLOOKUP(P4,スクリプト_フロー!$A:$F,4,FALSE),"") | K4: 未架電 | P4: =G4&"|"&H4 -> ①架電| | Q4: =IFERROR(VLOOKUP(P4,スクリプト_フロー!$A:$F,5,FALSE),"") | R4: =IF(J4="","",J4) | T4: =IF(DA4="","",SUBSTITUTE(SUBSTITUTE(SUBSTITUTE(SUBSTITUTE(SUBSTITUTE(SUBSTITUTE(SUBSTITUTE(SUBSTITUTE(SUBSTITUTE(SUBSTITUTE(SUBSTITUTE(DA4,"{会社}",設定!$B$3),"{自分}",設定!$B$4),"{サービス}",設定!$B$5),"{料金}",設定!$B$7),"{日付1}",設定!$B$8),"{日付2}",設定!$B$9),"{時間1}",設定!$B$10),"{時間2}",設定!$B$11),"{時間}","（指定時間）"),"{日付確定}","（確定日）"),"{時間確定}","（確定時間）")) | U4: =IFERROR(VLOOKUP(CZ4,スクリプト_フロー!$A:$F,4,FALSE),"") | V4: =IF(U4="","",U4) | X4: =IF(DC4="","",SUBSTITUTE(SUBSTITUTE(SUBSTITUTE(SUBSTITUTE(SUBSTITUTE(SUBSTITUTE(SUBSTITUTE(SUBSTITUTE(SUBSTITUTE(SUBSTITUTE(SUBSTITUTE(DC4,"{会社}",設定!$B$3),"{自分}",設定!$B$4),"{サービス}",設定!$B$5),"{料金}",設定!$B$7),"{日付1}",設定!$B$8),"{日付2}",設定!$B$9),"{時間1}",設定!$B$10),"{時間2}",設定!$B$11),"{時間}","（指定時間）"),"{日付確定}","（確定日）"),"{時間確定}","（確定時間）")) | Y4: =IFERROR(VLOOKUP(DB4,スクリプト_フロー!$A:$F,4,FALSE),"") | Z4: =IF(Y4="","",Y4) | AA4: ②受付 | AB4: =IF(DE4="","",SUBSTITUTE(SUBSTITUTE(SUBSTITUTE(SUBSTITUTE(SUBSTITUTE(SUBSTITUTE(SUBSTITUTE(SUBSTITUTE(SUBSTITUTE(SUBSTITUTE(SUBSTITUTE(DE4,"{会社}",設定!$B$3),"{自分}",設定!$B$4),"{サービス}",設定!$B$5),"{料金}",設定!$B$7),"{日付1}",設定!$B$8),"{日付2}",設定!$B$9),"{時間1}",設定!$B$10),"{時間2}",設定!$B$11),"{時間}","（指定時間）"),"{日付確定}","（確定日）"),"{時間確定}","（確定時間）")) | AC4: =IFERROR(VLOOKUP(DD4,スクリプト_フロー!$A:$F,4,FALSE),"") | AD4: =IF(AC4="","",AC4) | AE4: RESPX_003 | AF4: =IF(DG4="","",SUBSTITUTE(SUBSTITUTE(SUBSTITUTE(SUBSTITUTE(SUBSTITUTE(SUBSTITUTE(SUBSTITUTE(SUBSTITUTE(SUBSTITUTE(SUBSTITUTE(SUBSTITUTE(DG4,"{会社}",設定!$B$3),"{自分}",設定!$B$4),"{サービス}",設定!$B$5),"{料金}",設定!$B$7),"{日付1}",設定!$B$8),"{日付2}",設定!$B$9),"{時間1}",設定!$B$10),"{時間2}",設定!$B$11),"{時間}","（指定時間）"),"{日付確定}","（確定日）"),"{時間確定}","（確定時間）")) | AG4: =IFERROR(VLOOKUP(DF4,スクリプト_フロー!$A:$F,4,FALSE),"") | CZ4: =R4&"|"&S4 -> | | DA4: =IFERROR(VLOOKUP(CZ4,スクリプト_フロー!$A:$F,5,FALSE),"") | DB4: =V4&"|"&W4 -> | | DC4: =IFERROR(VLOOKUP(DB4,スクリプト_フロー!$A:$F,5,FALSE),"") | DD4: =Z4&"|"&AA4 -> |②受付 | DE4: =IFERROR(VLOOKUP(DD4,スクリプト_フロー!$A:$F,5,FALSE),"") | DF4: =AD4&"|"&AE4 -> |RESPX_003 | DG4: =IFERROR(VLOOKUP(DF4,スクリプト_フロー!$A:$F,5,FALSE),"")
A5: 4 | B5: 西鉄リゾートイン別府 | C5: 0977-26-5151 | D5: 北浜 | G5: ①架電 | I5: =SUBSTITUTE(SUBSTITUTE(SUBSTITUTE(SUBSTITUTE(SUBSTITUTE(SUBSTITUTE(SUBSTITUTE(SUBSTITUTE(SUBSTITUTE(SUBSTITUTE(SUBSTITUTE(Q5,"{会社}",設定!$B$3),"{自分}",設定!$B$4),"{サービス}",設定!$B$5),"{料金}",設定!$B$7),"{日付1}",設定!$B$8),"{日付2}",設定!$B$9),"{時間1}",設定!$B$10),"{時間2}",設定!$B$11),"{時間}","（指定時間）"),"{日付確定}","（確定日）"),"{時間確定}","（確定時間）") | J5: =IFERROR(VLOOKUP(P5,スクリプト_フロー!$A:$F,4,FALSE),"") | K5: 未架電 | P5: =G5&"|"&H5 -> ①架電| | Q5: =IFERROR(VLOOKUP(P5,スクリプト_フロー!$A:$F,5,FALSE),"") | R5: =IF(J5="","",J5) | T5: =IF(DA5="","",SUBSTITUTE(SUBSTITUTE(SUBSTITUTE(SUBSTITUTE(SUBSTITUTE(SUBSTITUTE(SUBSTITUTE(SUBSTITUTE(SUBSTITUTE(SUBSTITUTE(SUBSTITUTE(DA5,"{会社}",設定!$B$3),"{自分}",設定!$B$4),"{サービス}",設定!$B$5),"{料金}",設定!$B$7),"{日付1}",設定!$B$8),"{日付2}",設定!$B$9),"{時間1}",設定!$B$10),"{時間2}",設定!$B$11),"{時間}","（指定時間）"),"{日付確定}","（確定日）"),"{時間確定}","（確定時間）")) | U5: =IFERROR(VLOOKUP(CZ5,スクリプト_フロー!$A:$F,4,FALSE),"") | V5: =IF(U5="","",U5) | X5: =IF(DC5="","",SUBSTITUTE(SUBSTITUTE(SUBSTITUTE(SUBSTITUTE(SUBSTITUTE(SUBSTITUTE(SUBSTITUTE(SUBSTITUTE(SUBSTITUTE(SUBSTITUTE(SUBSTITUTE(DC5,"{会社}",設定!$B$3),"{自分}",設定!$B$4),"{サービス}",設定!$B$5),"{料金}",設定!$B$7),"{日付1}",設定!$B$8),"{日付2}",設定!$B$9),"{時間1}",設定!$B$10),"{時間2}",設定!$B$11),"{時間}","（指定時間）"),"{日付確定}","（確定日）"),"{時間確定}","（確定時間）")) | Y5: =IFERROR(VLOOKUP(DB5,スクリプト_フロー!$A:$F,4,FALSE),"") | Z5: =IF(Y5="","",Y5) | AA5: ③受付用件 | AB5: =IF(DE5="","",SUBSTITUTE(SUBSTITUTE(SUBSTITUTE(SUBSTITUTE(SUBSTITUTE(SUBSTITUTE(SUBSTITUTE(SUBSTITUTE(SUBSTITUTE(SUBSTITUTE(SUBSTITUTE(DE5,"{会社}",設定!$B$3),"{自分}",設定!$B$4),"{サービス}",設定!$B$5),"{料金}",設定!$B$7),"{日付1}",設定!$B$8),"{日付2}",設定!$B$9),"{時間1}",設定!$B$10),"{時間2}",設定!$B$11),"{時間}","（指定時間）"),"{日付確定}","（確定日）"),"{時間確定}","（確定時間）")) | AC5: =IFERROR(VLOOKUP(DD5,スクリプト_フロー!$A:$F,4,FALSE),"") | AD5: =IF(AC5="","",AC5) | AE5: RESPX_004 | AF5: =IF(DG5="","",SUBSTITUTE(SUBSTITUTE(SUBSTITUTE(SUBSTITUTE(SUBSTITUTE(SUBSTITUTE(SUBSTITUTE(SUBSTITUTE(SUBSTITUTE(SUBSTITUTE(SUBSTITUTE(DG5,"{会社}",設定!$B$3),"{自分}",設定!$B$4),"{サービス}",設定!$B$5),"{料金}",設定!$B$7),"{日付1}",設定!$B$8),"{日付2}",設定!$B$9),"{時間1}",設定!$B$10),"{時間2}",設定!$B$11),"{時間}","（指定時間）"),"{日付確定}","（確定日）"),"{時間確定}","（確定時間）")) | AG5: =IFERROR(VLOOKUP(DF5,スクリプト_フロー!$A:$F,4,FALSE),"") | CZ5: =R5&"|"&S5 -> | | DA5: =IFERROR(VLOOKUP(CZ5,スクリプト_フロー!$A:$F,5,FALSE),"") | DB5: =V5&"|"&W5 -> | | DC5: =IFERROR(VLOOKUP(DB5,スクリプト_フロー!$A:$F,5,FALSE),"") | DD5: =Z5&"|"&AA5 -> |③受付用件 | DE5: =IFERROR(VLOOKUP(DD5,スクリプト_フロー!$A:$F,5,FALSE),"") | DF5: =AD5&"|"&AE5 -> |RESPX_004 | DG5: =IFERROR(VLOOKUP(DF5,スクリプト_フロー!$A:$F,5,FALSE),"")
A6: 5 | B6: 別府温泉 ホテル白菊 | C6: 0977-21-2111 | D6: 駅周辺 | G6: ①架電 | I6: =SUBSTITUTE(SUBSTITUTE(SUBSTITUTE(SUBSTITUTE(SUBSTITUTE(SUBSTITUTE(SUBSTITUTE(SUBSTITUTE(SUBSTITUTE(SUBSTITUTE(SUBSTITUTE(Q6,"{会社}",設定!$B$3),"{自分}",設定!$B$4),"{サービス}",設定!$B$5),"{料金}",設定!$B$7),"{日付1}",設定!$B$8),"{日付2}",設定!$B$9),"{時間1}",設定!$B$10),"{時間2}",設定!$B$11),"{時間}","（指定時間）"),"{日付確定}","（確定日）"),"{時間確定}","（確定時間）") | J6: =IFERROR(VLOOKUP(P6,スクリプト_フロー!$A:$F,4,FALSE),"") | K6: 未架電 | P6: =G6&"|"&H6 -> ①架電| | Q6: =IFERROR(VLOOKUP(P6,スクリプト_フロー!$A:$F,5,FALSE),"") | R6: =IF(J6="","",J6) | T6: =IF(DA6="","",SUBSTITUTE(SUBSTITUTE(SUBSTITUTE(SUBSTITUTE(SUBSTITUTE(SUBSTITUTE(SUBSTITUTE(SUBSTITUTE(SUBSTITUTE(SUBSTITUTE(SUBSTITUTE(DA6,"{会社}",設定!$B$3),"{自分}",設定!$B$4),"{サービス}",設定!$B$5),"{料金}",設定!$B$7),"{日付1}",設定!$B$8),"{日付2}",設定!$B$9),"{時間1}",設定!$B$10),"{時間2}",設定!$B$11),"{時間}","（指定時間）"),"{日付確定}","（確定日）"),"{時間確定}","（確定時間）")) | U6: =IFERROR(VLOOKUP(CZ6,スクリプト_フロー!$A:$F,4,FALSE),"") | V6: =IF(U6="","",U6) | X6: =IF(DC6="","",SUBSTITUTE(SUBSTITUTE(SUBSTITUTE(SUBSTITUTE(SUBSTITUTE(SUBSTITUTE(SUBSTITUTE(SUBSTITUTE(SUBSTITUTE(SUBSTITUTE(SUBSTITUTE(DC6,"{会社}",設定!$B$3),"{自分}",設定!$B$4),"{サービス}",設定!$B$5),"{料金}",設定!$B$7),"{日付1}",設定!$B$8),"{日付2}",設定!$B$9),"{時間1}",設定!$B$10),"{時間2}",設定!$B$11),"{時間}","（指定時間）"),"{日付確定}","（確定日）"),"{時間確定}","（確定時間）")) | Y6: =IFERROR(VLOOKUP(DB6,スクリプト_フロー!$A:$F,4,FALSE),"") | Z6: =IF(Y6="","",Y6) | AA6: ④不在対応 | AB6: =IF(DE6="","",SUBSTITUTE(SUBSTITUTE(SUBSTITUTE(SUBSTITUTE(SUBSTITUTE(SUBSTITUTE(SUBSTITUTE(SUBSTITUTE(SUBSTITUTE(SUBSTITUTE(SUBSTITUTE(DE6,"{会社}",設定!$B$3),"{自分}",設定!$B$4),"{サービス}",設定!$B$5),"{料金}",設定!$B$7),"{日付1}",設定!$B$8),"{日付2}",設定!$B$9),"{時間1}",設定!$B$10),"{時間2}",設定!$B$11),"{時間}","（指定時間）"),"{日付確定}","（確定日）"),"{時間確定}","（確定時間）")) | AC6: =IFERROR(VLOOKUP(DD6,スクリプト_フロー!$A:$F,4,FALSE),"") | AD6: =IF(AC6="","",AC6) | AE6: RESPX_005 | AF6: =IF(DG6="","",SUBSTITUTE(SUBSTITUTE(SUBSTITUTE(SUBSTITUTE(SUBSTITUTE(SUBSTITUTE(SUBSTITUTE(SUBSTITUTE(SUBSTITUTE(SUBSTITUTE(SUBSTITUTE(DG6,"{会社}",設定!$B$3),"{自分}",設定!$B$4),"{サービス}",設定!$B$5),"{料金}",設定!$B$7),"{日付1}",設定!$B$8),"{日付2}",設定!$B$9),"{時間1}",設定!$B$10),"{時間2}",設定!$B$11),"{時間}","（指定時間）"),"{日付確定}","（確定日）"),"{時間確定}","（確定時間）")) | AG6: =IFERROR(VLOOKUP(DF6,スクリプト_フロー!$A:$F,4,FALSE),"") | CZ6: =R6&"|"&S6 -> | | DA6: =IFERROR(VLOOKUP(CZ6,スクリプト_フロー!$A:$F,5,FALSE),"") | DB6: =V6&"|"&W6 -> | | DC6: =IFERROR(VLOOKUP(DB6,スクリプト_フロー!$A:$F,5,FALSE),"") | DD6: =Z6&"|"&AA6 -> |④不在対応 | DE6: =IFERROR(VLOOKUP(DD6,スクリプト_フロー!$A:$F,5,FALSE),"") | DF6: =AD6&"|"&AE6 -> |RESPX_005 | DG6: =IFERROR(VLOOKUP(DF6,スクリプト_フロー!$A:$F,5,FALSE),"")
A7: 6 | B7: 竹と椿のお宿 花べっぷ | C7: 0977-21-0050 | D7: 北浜 | G7: ①架電 | I7: =SUBSTITUTE(SUBSTITUTE(SUBSTITUTE(SUBSTITUTE(SUBSTITUTE(SUBSTITUTE(SUBSTITUTE(SUBSTITUTE(SUBSTITUTE(SUBSTITUTE(SUBSTITUTE(Q7,"{会社}",設定!$B$3),"{自分}",設定!$B$4),"{サービス}",設定!$B$5),"{料金}",設定!$B$7),"{日付1}",設定!$B$8),"{日付2}",設定!$B$9),"{時間1}",設定!$B$10),"{時間2}",設定!$B$11),"{時間}","（指定時間）"),"{日付確定}","（確定日）"),"{時間確定}","（確定時間）") | J7: =IFERROR(VLOOKUP(P7,スクリプト_フロー!$A:$F,4,FALSE),"") | K7: 未架電 | P7: =G7&"|"&H7 -> ①架電| | Q7: =IFERROR(VLOOKUP(P7,スクリプト_フロー!$A:$F,5,FALSE),"") | R7: =IF(J7="","",J7) | T7: =IF(DA7="","",SUBSTITUTE(SUBSTITUTE(SUBSTITUTE(SUBSTITUTE(SUBSTITUTE(SUBSTITUTE(SUBSTITUTE(SUBSTITUTE(SUBSTITUTE(SUBSTITUTE(SUBSTITUTE(DA7,"{会社}",設定!$B$3),"{自分}",設定!$B$4),"{サービス}",設定!$B$5),"{料金}",設定!$B$7),"{日付1}",設定!$B$8),"{日付2}",設定!$B$9),"{時間1}",設定!$B$10),"{時間2}",設定!$B$11),"{時間}","（指定時間）"),"{日付確定}","（確定日）"),"{時間確定}","（確定時間）")) | U7: =IFERROR(VLOOKUP(CZ7,スクリプト_フロー!$A:$F,4,FALSE),"") | V7: =IF(U7="","",U7) | X7: =IF(DC7="","",SUBSTITUTE(SUBSTITUTE(SUBSTITUTE(SUBSTITUTE(SUBSTITUTE(SUBSTITUTE(SUBSTITUTE(SUBSTITUTE(SUBSTITUTE(SUBSTITUTE(SUBSTITUTE(DC7,"{会社}",設定!$B$3),"{自分}",設定!$B$4),"{サービス}",設定!$B$5),"{料金}",設定!$B$7),"{日付1}",設定!$B$8),"{日付2}",設定!$B$9),"{時間1}",設定!$B$10),"{時間2}",設定!$B$11),"{時間}","（指定時間）"),"{日付確定}","（確定日）"),"{時間確定}","（確定時間）")) | Y7: =IFERROR(VLOOKUP(DB7,スクリプト_フロー!$A:$F,4,FALSE),"") | Z7: =IF(Y7="","",Y7) | AA7: ⑤資料送付打診 | AB7: =IF(DE7="","",SUBSTITUTE(SUBSTITUTE(SUBSTITUTE(SUBSTITUTE(SUBSTITUTE(SUBSTITUTE(SUBSTITUTE(SUBSTITUTE(SUBSTITUTE(SUBSTITUTE(SUBSTITUTE(DE7,"{会社}",設定!$B$3),"{自分}",設定!$B$4),"{サービス}",設定!$B$5),"{料金}",設定!$B$7),"{日付1}",設定!$B$8),"{日付2}",設定!$B$9),"{時間1}",設定!$B$10),"{時間2}",設定!$B$11),"{時間}","（指定時間）"),"{日付確定}","（確定日）"),"{時間確定}","（確定時間）")) | AC7: =IFERROR(VLOOKUP(DD7,スクリプト_フロー!$A:$F,4,FALSE),"") | AD7: =IF(AC7="","",AC7) | AE7: RESPX_006 | AF7: =IF(DG7="","",SUBSTITUTE(SUBSTITUTE(SUBSTITUTE(SUBSTITUTE(SUBSTITUTE(SUBSTITUTE(SUBSTITUTE(SUBSTITUTE(SUBSTITUTE(SUBSTITUTE(SUBSTITUTE(DG7,"{会社}",設定!$B$3),"{自分}",設定!$B$4),"{サービス}",設定!$B$5),"{料金}",設定!$B$7),"{日付1}",設定!$B$8),"{日付2}",設定!$B$9),"{時間1}",設定!$B$10),"{時間2}",設定!$B$11),"{時間}","（指定時間）"),"{日付確定}","（確定日）"),"{時間確定}","（確定時間）")) | AG7: =IFERROR(VLOOKUP(DF7,スクリプト_フロー!$A:$F,4,FALSE),"") | CZ7: =R7&"|"&S7 -> | | DA7: =IFERROR(VLOOKUP(CZ7,スクリプト_フロー!$A:$F,5,FALSE),"") | DB7: =V7&"|"&W7 -> | | DC7: =IFERROR(VLOOKUP(DB7,スクリプト_フロー!$A:$F,5,FALSE),"") | DD7: =Z7&"|"&AA7 -> |⑤資料送付打診 | DE7: =IFERROR(VLOOKUP(DD7,スクリプト_フロー!$A:$F,5,FALSE),"") | DF7: =AD7&"|"&AE7 -> |RESPX_006 | DG7: =IFERROR(VLOOKUP(DF7,スクリプト_フロー!$A:$F,5,FALSE),"")
A8: 7 | B8: おにやまホテル | C8: 0977-66-1121 | D8: 鉄輪 | G8: ①架電 | I8: =SUBSTITUTE(SUBSTITUTE(SUBSTITUTE(SUBSTITUTE(SUBSTITUTE(SUBSTITUTE(SUBSTITUTE(SUBSTITUTE(SUBSTITUTE(SUBSTITUTE(SUBSTITUTE(Q8,"{会社}",設定!$B$3),"{自分}",設定!$B$4),"{サービス}",設定!$B$5),"{料金}",設定!$B$7),"{日付1}",設定!$B$8),"{日付2}",設定!$B$9),"{時間1}",設定!$B$10),"{時間2}",設定!$B$11),"{時間}","（指定時間）"),"{日付確定}","（確定日）"),"{時間確定}","（確定時間）") | J8: =IFERROR(VLOOKUP(P8,スクリプト_フロー!$A:$F,4,FALSE),"") | K8: 未架電 | P8: =G8&"|"&H8 -> ①架電| | Q8: =IFERROR(VLOOKUP(P8,スクリプト_フロー!$A:$F,5,FALSE),"") | R8: =IF(J8="","",J8) | T8: =IF(DA8="","",SUBSTITUTE(SUBSTITUTE(SUBSTITUTE(SUBSTITUTE(SUBSTITUTE(SUBSTITUTE(SUBSTITUTE(SUBSTITUTE(SUBSTITUTE(SUBSTITUTE(SUBSTITUTE(DA8,"{会社}",設定!$B$3),"{自分}",設定!$B$4),"{サービス}",設定!$B$5),"{料金}",設定!$B$7),"{日付1}",設定!$B$8),"{日付2}",設定!$B$9),"{時間1}",設定!$B$10),"{時間2}",設定!$B$11),"{時間}","（指定時間）"),"{日付確定}","（確定日）"),"{時間確定}","（確定時間）")) | U8: =IFERROR(VLOOKUP(CZ8,スクリプト_フロー!$A:$F,4,FALSE),"") | V8: =IF(U8="","",U8) | X8: =IF(DC8="","",SUBSTITUTE(SUBSTITUTE(SUBSTITUTE(SUBSTITUTE(SUBSTITUTE(SUBSTITUTE(SUBSTITUTE(SUBSTITUTE(SUBSTITUTE(SUBSTITUTE(SUBSTITUTE(DC8,"{会社}",設定!$B$3),"{自分}",設定!$B$4),"{サービス}",設定!$B$5),"{料金}",設定!$B$7),"{日付1}",設定!$B$8),"{日付2}",設定!$B$9),"{時間1}",設定!$B$10),"{時間2}",設定!$B$11),"{時間}","（指定時間）"),"{日付確定}","（確定日）"),"{時間確定}","（確定時間）")) | Y8: =IFERROR(VLOOKUP(DB8,スクリプト_フロー!$A:$F,4,FALSE),"") | Z8: =IF(Y8="","",Y8) | AA8: ⑥目的伝達 | AB8: =IF(DE8="","",SUBSTITUTE(SUBSTITUTE(SUBSTITUTE(SUBSTITUTE(SUBSTITUTE(SUBSTITUTE(SUBSTITUTE(SUBSTITUTE(SUBSTITUTE(SUBSTITUTE(SUBSTITUTE(DE8,"{会社}",設定!$B$3),"{自分}",設定!$B$4),"{サービス}",設定!$B$5),"{料金}",設定!$B$7),"{日付1}",設定!$B$8),"{日付2}",設定!$B$9),"{時間1}",設定!$B$10),"{時間2}",設定!$B$11),"{時間}","（指定時間）"),"{日付確定}","（確定日）"),"{時間確定}","（確定時間）")) | AC8: =IFERROR(VLOOKUP(DD8,スクリプト_フロー!$A:$F,4,FALSE),"") | AD8: =IF(AC8="","",AC8) | AE8: RESPX_007 | AF8: =IF(DG8="","",SUBSTITUTE(SUBSTITUTE(SUBSTITUTE(SUBSTITUTE(SUBSTITUTE(SUBSTITUTE(SUBSTITUTE(SUBSTITUTE(SUBSTITUTE(SUBSTITUTE(SUBSTITUTE(DG8,"{会社}",設定!$B$3),"{自分}",設定!$B$4),"{サービス}",設定!$B$5),"{料金}",設定!$B$7),"{日付1}",設定!$B$8),"{日付2}",設定!$B$9),"{時間1}",設定!$B$10),"{時間2}",設定!$B$11),"{時間}","（指定時間）"),"{日付確定}","（確定日）"),"{時間確定}","（確定時間）")) | AG8: =IFERROR(VLOOKUP(DF8,スクリプト_フロー!$A:$F,4,FALSE),"") | CZ8: =R8&"|"&S8 -> | | DA8: =IFERROR(VLOOKUP(CZ8,スクリプト_フロー!$A:$F,5,FALSE),"") | DB8: =V8&"|"&W8 -> | | DC8: =IFERROR(VLOOKUP(DB8,スクリプト_フロー!$A:$F,5,FALSE),"") | DD8: =Z8&"|"&AA8 -> |⑥目的伝達 | DE8: =IFERROR(VLOOKUP(DD8,スクリプト_フロー!$A:$F,5,FALSE),"") | DF8: =AD8&"|"&AE8 -> |RESPX_007 | DG8: =IFERROR(VLOOKUP(DF8,スクリプト_フロー!$A:$F,5,FALSE),"")
A9: 8 | B9: 別府八湯 御宿 野乃別府 | C9: 0977-21-5489 | D9: 別府駅周辺 | G9: ①架電 | I9: =SUBSTITUTE(SUBSTITUTE(SUBSTITUTE(SUBSTITUTE(SUBSTITUTE(SUBSTITUTE(SUBSTITUTE(SUBSTITUTE(SUBSTITUTE(SUBSTITUTE(SUBSTITUTE(Q9,"{会社}",設定!$B$3),"{自分}",設定!$B$4),"{サービス}",設定!$B$5),"{料金}",設定!$B$7),"{日付1}",設定!$B$8),"{日付2}",設定!$B$9),"{時間1}",設定!$B$10),"{時間2}",設定!$B$11),"{時間}","（指定時間）"),"{日付確定}","（確定日）"),"{時間確定}","（確定時間）") | J9: =IFERROR(VLOOKUP(P9,スクリプト_フロー!$A:$F,4,FALSE),"") | K9: 未架電 | P9: =G9&"|"&H9 -> ①架電| | Q9: =IFERROR(VLOOKUP(P9,スクリプト_フロー!$A:$F,5,FALSE),"") | R9: =IF(J9="","",J9) | T9: =IF(DA9="","",SUBSTITUTE(SUBSTITUTE(SUBSTITUTE(SUBSTITUTE(SUBSTITUTE(SUBSTITUTE(SUBSTITUTE(SUBSTITUTE(SUBSTITUTE(SUBSTITUTE(SUBSTITUTE(DA9,"{会社}",設定!$B$3),"{自分}",設定!$B$4),"{サービス}",設定!$B$5),"{料金}",設定!$B$7),"{日付1}",設定!$B$8),"{日付2}",設定!$B$9),"{時間1}",設定!$B$10),"{時間2}",設定!$B$11),"{時間}","（指定時間）"),"{日付確定}","（確定日）"),"{時間確定}","（確定時間）")) | U9: =IFERROR(VLOOKUP(CZ9,スクリプト_フロー!$A:$F,4,FALSE),"") | V9: =IF(U9="","",U9) | X9: =IF(DC9="","",SUBSTITUTE(SUBSTITUTE(SUBSTITUTE(SUBSTITUTE(SUBSTITUTE(SUBSTITUTE(SUBSTITUTE(SUBSTITUTE(SUBSTITUTE(SUBSTITUTE(SUBSTITUTE(DC9,"{会社}",設定!$B$3),"{自分}",設定!$B$4),"{サービス}",設定!$B$5),"{料金}",設定!$B$7),"{日付1}",設定!$B$8),"{日付2}",設定!$B$9),"{時間1}",設定!$B$10),"{時間2}",設定!$B$11),"{時間}","（指定時間）"),"{日付確定}","（確定日）"),"{時間確定}","（確定時間）")) | Y9: =IFERROR(VLOOKUP(DB9,スクリプト_フロー!$A:$F,4,FALSE),"") | Z9: =IF(Y9="","",Y9) | AA9: ⑦メリット | AB9: =IF(DE9="","",SUBSTITUTE(SUBSTITUTE(SUBSTITUTE(SUBSTITUTE(SUBSTITUTE(SUBSTITUTE(SUBSTITUTE(SUBSTITUTE(SUBSTITUTE(SUBSTITUTE(SUBSTITUTE(DE9,"{会社}",設定!$B$3),"{自分}",設定!$B$4),"{サービス}",設定!$B$5),"{料金}",設定!$B$7),"{日付1}",設定!$B$8),"{日付2}",設定!$B$9),"{時間1}",設定!$B$10),"{時間2}",設定!$B$11),"{時間}","（指定時間）"),"{日付確定}","（確定日）"),"{時間確定}","（確定時間）")) | AC9: =IFERROR(VLOOKUP(DD9,スクリプト_フロー!$A:$F,4,FALSE),"") | AD9: =IF(AC9="","",AC9) | AE9: RESPX_008 | AF9: =IF(DG9="","",SUBSTITUTE(SUBSTITUTE(SUBSTITUTE(SUBSTITUTE(SUBSTITUTE(SUBSTITUTE(SUBSTITUTE(SUBSTITUTE(SUBSTITUTE(SUBSTITUTE(SUBSTITUTE(DG9,"{会社}",設定!$B$3),"{自分}",設定!$B$4),"{サービス}",設定!$B$5),"{料金}",設定!$B$7),"{日付1}",設定!$B$8),"{日付2}",設定!$B$9),"{時間1}",設定!$B$10),"{時間2}",設定!$B$11),"{時間}","（指定時間）"),"{日付確定}","（確定日）"),"{時間確定}","（確定時間）")) | AG9: =IFERROR(VLOOKUP(DF9,スクリプト_フロー!$A:$F,4,FALSE),"") | CZ9: =R9&"|"&S9 -> | | DA9: =IFERROR(VLOOKUP(CZ9,スクリプト_フロー!$A:$F,5,FALSE),"") | DB9: =V9&"|"&W9 -> | | DC9: =IFERROR(VLOOKUP(DB9,スクリプト_フロー!$A:$F,5,FALSE),"") | DD9: =Z9&"|"&AA9 -> |⑦メリット | DE9: =IFERROR(VLOOKUP(DD9,スクリプト_フロー!$A:$F,5,FALSE),"") | DF9: =AD9&"|"&AE9 -> |RESPX_008 | DG9: =IFERROR(VLOOKUP(DF9,スクリプト_フロー!$A:$F,5,FALSE),"")
A10: 9 | B10: アマネク別府ゆらり | C10: 0977-76-5566 | D10: 別府駅周辺 | G10: ①架電 | I10: =SUBSTITUTE(SUBSTITUTE(SUBSTITUTE(SUBSTITUTE(SUBSTITUTE(SUBSTITUTE(SUBSTITUTE(SUBSTITUTE(SUBSTITUTE(SUBSTITUTE(SUBSTITUTE(Q10,"{会社}",設定!$B$3),"{自分}",設定!$B$4),"{サービス}",設定!$B$5),"{料金}",設定!$B$7),"{日付1}",設定!$B$8),"{日付2}",設定!$B$9),"{時間1}",設定!$B$10),"{時間2}",設定!$B$11),"{時間}","（指定時間）"),"{日付確定}","（確定日）"),"{時間確定}","（確定時間）") | J10: =IFERROR(VLOOKUP(P10,スクリプト_フロー!$A:$F,4,FALSE),"") | K10: 未架電 | P10: =G10&"|"&H10 -> ①架電| | Q10: =IFERROR(VLOOKUP(P10,スクリプト_フロー!$A:$F,5,FALSE),"") | R10: =IF(J10="","",J10) | T10: =IF(DA10="","",SUBSTITUTE(SUBSTITUTE(SUBSTITUTE(SUBSTITUTE(SUBSTITUTE(SUBSTITUTE(SUBSTITUTE(SUBSTITUTE(SUBSTITUTE(SUBSTITUTE(SUBSTITUTE(DA10,"{会社}",設定!$B$3),"{自分}",設定!$B$4),"{サービス}",設定!$B$5),"{料金}",設定!$B$7),"{日付1}",設定!$B$8),"{日付2}",設定!$B$9),"{時間1}",設定!$B$10),"{時間2}",設定!$B$11),"{時間}","（指定時間）"),"{日付確定}","（確定日）"),"{時間確定}","（確定時間）")) | U10: =IFERROR(VLOOKUP(CZ10,スクリプト_フロー!$A:$F,4,FALSE),"") | V10: =IF(U10="","",U10) | X10: =IF(DC10="","",SUBSTITUTE(SUBSTITUTE(SUBSTITUTE(SUBSTITUTE(SUBSTITUTE(SUBSTITUTE(SUBSTITUTE(SUBSTITUTE(SUBSTITUTE(SUBSTITUTE(SUBSTITUTE(DC10,"{会社}",設定!$B$3),"{自分}",設定!$B$4),"{サービス}",設定!$B$5),"{料金}",設定!$B$7),"{日付1}",設定!$B$8),"{日付2}",設定!$B$9),"{時間1}",設定!$B$10),"{時間2}",設定!$B$11),"{時間}","（指定時間）"),"{日付確定}","（確定日）"),"{時間確定}","（確定時間）")) | Y10: =IFERROR(VLOOKUP(DB10,スクリプト_フロー!$A:$F,4,FALSE),"") | Z10: =IF(Y10="","",Y10) | AA10: ⑧費用説明 | AB10: =IF(DE10="","",SUBSTITUTE(SUBSTITUTE(SUBSTITUTE(SUBSTITUTE(SUBSTITUTE(SUBSTITUTE(SUBSTITUTE(SUBSTITUTE(SUBSTITUTE(SUBSTITUTE(SUBSTITUTE(DE10,"{会社}",設定!$B$3),"{自分}",設定!$B$4),"{サービス}",設定!$B$5),"{料金}",設定!$B$7),"{日付1}",設定!$B$8),"{日付2}",設定!$B$9),"{時間1}",設定!$B$10),"{時間2}",設定!$B$11),"{時間}","（指定時間）"),"{日付確定}","（確定日）"),"{時間確定}","（確定時間）")) | AC10: =IFERROR(VLOOKUP(DD10,スクリプト_フロー!$A:$F,4,FALSE),"") | AD10: =IF(AC10="","",AC10) | AE10: RESPX_009 | AF10: =IF(DG10="","",SUBSTITUTE(SUBSTITUTE(SUBSTITUTE(SUBSTITUTE(SUBSTITUTE(SUBSTITUTE(SUBSTITUTE(SUBSTITUTE(SUBSTITUTE(SUBSTITUTE(SUBSTITUTE(DG10,"{会社}",設定!$B$3),"{自分}",設定!$B$4),"{サービス}",設定!$B$5),"{料金}",設定!$B$7),"{日付1}",設定!$B$8),"{日付2}",設定!$B$9),"{時間1}",設定!$B$10),"{時間2}",設定!$B$11),"{時間}","（指定時間）"),"{日付確定}","（確定日）"),"{時間確定}","（確定時間）")) | AG10: =IFERROR(VLOOKUP(DF10,スクリプト_フロー!$A:$F,4,FALSE),"") | CZ10: =R10&"|"&S10 -> | | DA10: =IFERROR(VLOOKUP(CZ10,スクリプト_フロー!$A:$F,5,FALSE),"") | DB10: =V10&"|"&W10 -> | | DC10: =IFERROR(VLOOKUP(DB10,スクリプト_フロー!$A:$F,5,FALSE),"") | DD10: =Z10&"|"&AA10 -> |⑧費用説明 | DE10: =IFERROR(VLOOKUP(DD10,スクリプト_フロー!$A:$F,5,FALSE),"") | DF10: =AD10&"|"&AE10 -> |RESPX_009 | DG10: =IFERROR(VLOOKUP(DF10,スクリプト_フロー!$A:$F,5,FALSE),"")
A11: 10 | B11: アマネクイン別府 | C11: 0977-76-5565 | D11: 別府駅周辺 | G11: ①架電 | I11: =SUBSTITUTE(SUBSTITUTE(SUBSTITUTE(SUBSTITUTE(SUBSTITUTE(SUBSTITUTE(SUBSTITUTE(SUBSTITUTE(SUBSTITUTE(SUBSTITUTE(SUBSTITUTE(Q11,"{会社}",設定!$B$3),"{自分}",設定!$B$4),"{サービス}",設定!$B$5),"{料金}",設定!$B$7),"{日付1}",設定!$B$8),"{日付2}",設定!$B$9),"{時間1}",設定!$B$10),"{時間2}",設定!$B$11),"{時間}","（指定時間）"),"{日付確定}","（確定日）"),"{時間確定}","（確定時間）") | J11: =IFERROR(VLOOKUP(P11,スクリプト_フロー!$A:$F,4,FALSE),"") | K11: 未架電 | P11: =G11&"|"&H11 -> ①架電| | Q11: =IFERROR(VLOOKUP(P11,スクリプト_フロー!$A:$F,5,FALSE),"") | R11: =IF(J11="","",J11) | T11: =IF(DA11="","",SUBSTITUTE(SUBSTITUTE(SUBSTITUTE(SUBSTITUTE(SUBSTITUTE(SUBSTITUTE(SUBSTITUTE(SUBSTITUTE(SUBSTITUTE(SUBSTITUTE(SUBSTITUTE(DA11,"{会社}",設定!$B$3),"{自分}",設定!$B$4),"{サービス}",設定!$B$5),"{料金}",設定!$B$7),"{日付1}",設定!$B$8),"{日付2}",設定!$B$9),"{時間1}",設定!$B$10),"{時間2}",設定!$B$11),"{時間}","（指定時間）"),"{日付確定}","（確定日）"),"{時間確定}","（確定時間）")) | U11: =IFERROR(VLOOKUP(CZ11,スクリプト_フロー!$A:$F,4,FALSE),"") | V11: =IF(U11="","",U11) | X11: =IF(DC11="","",SUBSTITUTE(SUBSTITUTE(SUBSTITUTE(SUBSTITUTE(SUBSTITUTE(SUBSTITUTE(SUBSTITUTE(SUBSTITUTE(SUBSTITUTE(SUBSTITUTE(SUBSTITUTE(DC11,"{会社}",設定!$B$3),"{自分}",設定!$B$4),"{サービス}",設定!$B$5),"{料金}",設定!$B$7),"{日付1}",設定!$B$8),"{日付2}",設定!$B$9),"{時間1}",設定!$B$10),"{時間2}",設定!$B$11),"{時間}","（指定時間）"),"{日付確定}","（確定日）"),"{時間確定}","（確定時間）")) | Y11: =IFERROR(VLOOKUP(DB11,スクリプト_フロー!$A:$F,4,FALSE),"") | Z11: =IF(Y11="","",Y11) | AA11: ⑨安全説明 | AB11: =IF(DE11="","",SUBSTITUTE(SUBSTITUTE(SUBSTITUTE(SUBSTITUTE(SUBSTITUTE(SUBSTITUTE(SUBSTITUTE(SUBSTITUTE(SUBSTITUTE(SUBSTITUTE(SUBSTITUTE(DE11,"{会社}",設定!$B$3),"{自分}",設定!$B$4),"{サービス}",設定!$B$5),"{料金}",設定!$B$7),"{日付1}",設定!$B$8),"{日付2}",設定!$B$9),"{時間1}",設定!$B$10),"{時間2}",設定!$B$11),"{時間}","（指定時間）"),"{日付確定}","（確定日）"),"{時間確定}","（確定時間）")) | AC11: =IFERROR(VLOOKUP(DD11,スクリプト_フロー!$A:$F,4,FALSE),"") | AD11: =IF(AC11="","",AC11) | AE11: RESPX_010 | AF11: =IF(DG11="","",SUBSTITUTE(SUBSTITUTE(SUBSTITUTE(SUBSTITUTE(SUBSTITUTE(SUBSTITUTE(SUBSTITUTE(SUBSTITUTE(SUBSTITUTE(SUBSTITUTE(SUBSTITUTE(DG11,"{会社}",設定!$B$3),"{自分}",設定!$B$4),"{サービス}",設定!$B$5),"{料金}",設定!$B$7),"{日付1}",設定!$B$8),"{日付2}",設定!$B$9),"{時間1}",設定!$B$10),"{時間2}",設定!$B$11),"{時間}","（指定時間）"),"{日付確定}","（確定日）"),"{時間確定}","（確定時間）")) | AG11: =IFERROR(VLOOKUP(DF11,スクリプト_フロー!$A:$F,4,FALSE),"") | CZ11: =R11&"|"&S11 -> | | DA11: =IFERROR(VLOOKUP(CZ11,スクリプト_フロー!$A:$F,5,FALSE),"") | DB11: =V11&"|"&W11 -> | | DC11: =IFERROR(VLOOKUP(DB11,スクリプト_フロー!$A:$F,5,FALSE),"") | DD11: =Z11&"|"&AA11 -> |⑨安全説明 | DE11: =IFERROR(VLOOKUP(DD11,スクリプト_フロー!$A:$F,5,FALSE),"") | DF11: =AD11&"|"&AE11 -> |RESPX_010 | DG11: =IFERROR(VLOOKUP(DF11,スクリプト_フロー!$A:$F,5,FALSE),"")
A12: 11 | B12: MURE Beppu | C12: 0977-23-3377 | D12: 楠町（ゆめタウン周辺） | G12: ①架電 | I12: =SUBSTITUTE(SUBSTITUTE(SUBSTITUTE(SUBSTITUTE(SUBSTITUTE(SUBSTITUTE(SUBSTITUTE(SUBSTITUTE(SUBSTITUTE(SUBSTITUTE(SUBSTITUTE(Q12,"{会社}",設定!$B$3),"{自分}",設定!$B$4),"{サービス}",設定!$B$5),"{料金}",設定!$B$7),"{日付1}",設定!$B$8),"{日付2}",設定!$B$9),"{時間1}",設定!$B$10),"{時間2}",設定!$B$11),"{時間}","（指定時間）"),"{日付確定}","（確定日）"),"{時間確定}","（確定時間）") | J12: =IFERROR(VLOOKUP(P12,スクリプト_フロー!$A:$F,4,FALSE),"") | K12: 未架電 | P12: =G12&"|"&H12 -> ①架電| | Q12: =IFERROR(VLOOKUP(P12,スクリプト_フロー!$A:$F,5,FALSE),"") | R12: =IF(J12="","",J12) | T12: =IF(DA12="","",SUBSTITUTE(SUBSTITUTE(SUBSTITUTE(SUBSTITUTE(SUBSTITUTE(SUBSTITUTE(SUBSTITUTE(SUBSTITUTE(SUBSTITUTE(SUBSTITUTE(SUBSTITUTE(DA12,"{会社}",設定!$B$3),"{自分}",設定!$B$4),"{サービス}",設定!$B$5),"{料金}",設定!$B$7),"{日付1}",設定!$B$8),"{日付2}",設定!$B$9),"{時間1}",設定!$B$10),"{時間2}",設定!$B$11),"{時間}","（指定時間）"),"{日付確定}","（確定日）"),"{時間確定}","（確定時間）")) | U12: =IFERROR(VLOOKUP(CZ12,スクリプト_フロー!$A:$F,4,FALSE),"") | V12: =IF(U12="","",U12) | X12: =IF(DC12="","",SUBSTITUTE(SUBSTITUTE(SUBSTITUTE(SUBSTITUTE(SUBSTITUTE(SUBSTITUTE(SUBSTITUTE(SUBSTITUTE(SUBSTITUTE(SUBSTITUTE(SUBSTITUTE(DC12,"{会社}",設定!$B$3),"{自分}",設定!$B$4),"{サービス}",設定!$B$5),"{料金}",設定!$B$7),"{日付1}",設定!$B$8),"{日付2}",設定!$B$9),"{時間1}",設定!$B$10),"{時間2}",設定!$B$11),"{時間}","（指定時間）"),"{日付確定}","（確定日）"),"{時間確定}","（確定時間）")) | Y12: =IFERROR(VLOOKUP(DB12,スクリプト_フロー!$A:$F,4,FALSE),"") | Z12: =IF(Y12="","",Y12) | AA12: ⑩ヒアリング | AB12: =IF(DE12="","",SUBSTITUTE(SUBSTITUTE(SUBSTITUTE(SUBSTITUTE(SUBSTITUTE(SUBSTITUTE(SUBSTITUTE(SUBSTITUTE(SUBSTITUTE(SUBSTITUTE(SUBSTITUTE(DE12,"{会社}",設定!$B$3),"{自分}",設定!$B$4),"{サービス}",設定!$B$5),"{料金}",設定!$B$7),"{日付1}",設定!$B$8),"{日付2}",設定!$B$9),"{時間1}",設定!$B$10),"{時間2}",設定!$B$11),"{時間}","（指定時間）"),"{日付確定}","（確定日）"),"{時間確定}","（確定時間）")) | AC12: =IFERROR(VLOOKUP(DD12,スクリプト_フロー!$A:$F,4,FALSE),"") | AD12: =IF(AC12="","",AC12) | AE12: RESPX_011 | AF12: =IF(DG12="","",SUBSTITUTE(SUBSTITUTE(SUBSTITUTE(SUBSTITUTE(SUBSTITUTE(SUBSTITUTE(SUBSTITUTE(SUBSTITUTE(SUBSTITUTE(SUBSTITUTE(SUBSTITUTE(DG12,"{会社}",設定!$B$3),"{自分}",設定!$B$4),"{サービス}",設定!$B$5),"{料金}",設定!$B$7),"{日付1}",設定!$B$8),"{日付2}",設定!$B$9),"{時間1}",設定!$B$10),"{時間2}",設定!$B$11),"{時間}","（指定時間）"),"{日付確定}","（確定日）"),"{時間確定}","（確定時間）")) | AG12: =IFERROR(VLOOKUP(DF12,スクリプト_フロー!$A:$F,4,FALSE),"") | CZ12: =R12&"|"&S12 -> | | DA12: =IFERROR(VLOOKUP(CZ12,スクリプト_フロー!$A:$F,5,FALSE),"") | DB12: =V12&"|"&W12 -> | | DC12: =IFERROR(VLOOKUP(DB12,スクリプト_フロー!$A:$F,5,FALSE),"") | DD12: =Z12&"|"&AA12 -> |⑩ヒアリング | DE12: =IFERROR(VLOOKUP(DD12,スクリプト_フロー!$A:$F,5,FALSE),"") | DF12: =AD12&"|"&AE12 -> |RESPX_011 | DG12: =IFERROR(VLOOKUP(DF12,スクリプト_フロー!$A:$F,5,FALSE),"")
A13: 12 | B13: REX HOTEL別府 | C13: 0977-23-6111 | D13: 若草・餅ヶ浜 | G13: ①架電 | I13: =SUBSTITUTE(SUBSTITUTE(SUBSTITUTE(SUBSTITUTE(SUBSTITUTE(SUBSTITUTE(SUBSTITUTE(SUBSTITUTE(SUBSTITUTE(SUBSTITUTE(SUBSTITUTE(Q13,"{会社}",設定!$B$3),"{自分}",設定!$B$4),"{サービス}",設定!$B$5),"{料金}",設定!$B$7),"{日付1}",設定!$B$8),"{日付2}",設定!$B$9),"{時間1}",設定!$B$10),"{時間2}",設定!$B$11),"{時間}","（指定時間）"),"{日付確定}","（確定日）"),"{時間確定}","（確定時間）") | J13: =IFERROR(VLOOKUP(P13,スクリプト_フロー!$A:$F,4,FALSE),"") | K13: 未架電 | P13: =G13&"|"&H13 -> ①架電| | Q13: =IFERROR(VLOOKUP(P13,スクリプト_フロー!$A:$F,5,FALSE),"") | R13: =IF(J13="","",J13) | T13: =IF(DA13="","",SUBSTITUTE(SUBSTITUTE(SUBSTITUTE(SUBSTITUTE(SUBSTITUTE(SUBSTITUTE(SUBSTITUTE(SUBSTITUTE(SUBSTITUTE(SUBSTITUTE(SUBSTITUTE(DA13,"{会社}",設定!$B$3),"{自分}",設定!$B$4),"{サービス}",設定!$B$5),"{料金}",設定!$B$7),"{日付1}",設定!$B$8),"{日付2}",設定!$B$9),"{時間1}",設定!$B$10),"{時間2}",設定!$B$11),"{時間}","（指定時間）"),"{日付確定}","（確定日）"),"{時間確定}","（確定時間）")) | U13: =IFERROR(VLOOKUP(CZ13,スクリプト_フロー!$A:$F,4,FALSE),"") | V13: =IF(U13="","",U13) | X13: =IF(DC13="","",SUBSTITUTE(SUBSTITUTE(SUBSTITUTE(SUBSTITUTE(SUBSTITUTE(SUBSTITUTE(SUBSTITUTE(SUBSTITUTE(SUBSTITUTE(SUBSTITUTE(SUBSTITUTE(DC13,"{会社}",設定!$B$3),"{自分}",設定!$B$4),"{サービス}",設定!$B$5),"{料金}",設定!$B$7),"{日付1}",設定!$B$8),"{日付2}",設定!$B$9),"{時間1}",設定!$B$10),"{時間2}",設定!$B$11),"{時間}","（指定時間）"),"{日付確定}","（確定日）"),"{時間確定}","（確定時間）")) | Y13: =IFERROR(VLOOKUP(DB13,スクリプト_フロー!$A:$F,4,FALSE),"") | Z13: =IF(Y13="","",Y13) | AA13: ⑪代替案 | AB13: =IF(DE13="","",SUBSTITUTE(SUBSTITUTE(SUBSTITUTE(SUBSTITUTE(SUBSTITUTE(SUBSTITUTE(SUBSTITUTE(SUBSTITUTE(SUBSTITUTE(SUBSTITUTE(SUBSTITUTE(DE13,"{会社}",設定!$B$3),"{自分}",設定!$B$4),"{サービス}",設定!$B$5),"{料金}",設定!$B$7),"{日付1}",設定!$B$8),"{日付2}",設定!$B$9),"{時間1}",設定!$B$10),"{時間2}",設定!$B$11),"{時間}","（指定時間）"),"{日付確定}","（確定日）"),"{時間確定}","（確定時間）")) | AC13: =IFERROR(VLOOKUP(DD13,スクリプト_フロー!$A:$F,4,FALSE),"") | AD13: =IF(AC13="","",AC13) | AE13: RESPX_012 | AF13: =IF(DG13="","",SUBSTITUTE(SUBSTITUTE(SUBSTITUTE(SUBSTITUTE(SUBSTITUTE(SUBSTITUTE(SUBSTITUTE(SUBSTITUTE(SUBSTITUTE(SUBSTITUTE(SUBSTITUTE(DG13,"{会社}",設定!$B$3),"{自分}",設定!$B$4),"{サービス}",設定!$B$5),"{料金}",設定!$B$7),"{日付1}",設定!$B$8),"{日付2}",設定!$B$9),"{時間1}",設定!$B$10),"{時間2}",設定!$B$11),"{時間}","（指定時間）"),"{日付確定}","（確定日）"),"{時間確定}","（確定時間）")) | AG13: =IFERROR(VLOOKUP(DF13,スクリプト_フロー!$A:$F,4,FALSE),"") | CZ13: =R13&"|"&S13 -> | | DA13: =IFERROR(VLOOKUP(CZ13,スクリプト_フロー!$A:$F,5,FALSE),"") | DB13: =V13&"|"&W13 -> | | DC13: =IFERROR(VLOOKUP(DB13,スクリプト_フロー!$A:$F,5,FALSE),"") | DD13: =Z13&"|"&AA13 -> |⑪代替案 | DE13: =IFERROR(VLOOKUP(DD13,スクリプト_フロー!$A:$F,5,FALSE),"") | DF13: =AD13&"|"&AE13 -> |RESPX_012 | DG13: =IFERROR(VLOOKUP(DF13,スクリプト_フロー!$A:$F,5,FALSE),"")
A14: 13 | B14: 別府風雅 | C14: 0570-018-766 | D14: 堀田 | G14: ①架電 | I14: =SUBSTITUTE(SUBSTITUTE(SUBSTITUTE(SUBSTITUTE(SUBSTITUTE(SUBSTITUTE(SUBSTITUTE(SUBSTITUTE(SUBSTITUTE(SUBSTITUTE(SUBSTITUTE(Q14,"{会社}",設定!$B$3),"{自分}",設定!$B$4),"{サービス}",設定!$B$5),"{料金}",設定!$B$7),"{日付1}",設定!$B$8),"{日付2}",設定!$B$9),"{時間1}",設定!$B$10),"{時間2}",設定!$B$11),"{時間}","（指定時間）"),"{日付確定}","（確定日）"),"{時間確定}","（確定時間）") | J14: =IFERROR(VLOOKUP(P14,スクリプト_フロー!$A:$F,4,FALSE),"") | K14: 未架電 | P14: =G14&"|"&H14 -> ①架電| | Q14: =IFERROR(VLOOKUP(P14,スクリプト_フロー!$A:$F,5,FALSE),"") | R14: =IF(J14="","",J14) | T14: =IF(DA14="","",SUBSTITUTE(SUBSTITUTE(SUBSTITUTE(SUBSTITUTE(SUBSTITUTE(SUBSTITUTE(SUBSTITUTE(SUBSTITUTE(SUBSTITUTE(SUBSTITUTE(SUBSTITUTE(DA14,"{会社}",設定!$B$3),"{自分}",設定!$B$4),"{サービス}",設定!$B$5),"{料金}",設定!$B$7),"{日付1}",設定!$B$8),"{日付2}",設定!$B$9),"{時間1}",設定!$B$10),"{時間2}",設定!$B$11),"{時間}","（指定時間）"),"{日付確定}","（確定日）"),"{時間確定}","（確定時間）")) | U14: =IFERROR(VLOOKUP(CZ14,スクリプト_フロー!$A:$F,4,FALSE),"") | V14: =IF(U14="","",U14) | X14: =IF(DC14="","",SUBSTITUTE(SUBSTITUTE(SUBSTITUTE(SUBSTITUTE(SUBSTITUTE(SUBSTITUTE(SUBSTITUTE(SUBSTITUTE(SUBSTITUTE(SUBSTITUTE(SUBSTITUTE(DC14,"{会社}",設定!$B$3),"{自分}",設定!$B$4),"{サービス}",設定!$B$5),"{料金}",設定!$B$7),"{日付1}",設定!$B$8),"{日付2}",設定!$B$9),"{時間1}",設定!$B$10),"{時間2}",設定!$B$11),"{時間}","（指定時間）"),"{日付確定}","（確定日）"),"{時間確定}","（確定時間）")) | Y14: =IFERROR(VLOOKUP(DB14,スクリプト_フロー!$A:$F,4,FALSE),"") | Z14: =IF(Y14="","",Y14) | AA14: ⑫決裁者確認 | AB14: =IF(DE14="","",SUBSTITUTE(SUBSTITUTE(SUBSTITUTE(SUBSTITUTE(SUBSTITUTE(SUBSTITUTE(SUBSTITUTE(SUBSTITUTE(SUBSTITUTE(SUBSTITUTE(SUBSTITUTE(DE14,"{会社}",設定!$B$3),"{自分}",設定!$B$4),"{サービス}",設定!$B$5),"{料金}",設定!$B$7),"{日付1}",設定!$B$8),"{日付2}",設定!$B$9),"{時間1}",設定!$B$10),"{時間2}",設定!$B$11),"{時間}","（指定時間）"),"{日付確定}","（確定日）"),"{時間確定}","（確定時間）")) | AC14: =IFERROR(VLOOKUP(DD14,スクリプト_フロー!$A:$F,4,FALSE),"") | AD14: =IF(AC14="","",AC14) | AE14: RESPX_013 | AF14: =IF(DG14="","",SUBSTITUTE(SUBSTITUTE(SUBSTITUTE(SUBSTITUTE(SUBSTITUTE(SUBSTITUTE(SUBSTITUTE(SUBSTITUTE(SUBSTITUTE(SUBSTITUTE(SUBSTITUTE(DG14,"{会社}",設定!$B$3),"{自分}",設定!$B$4),"{サービス}",設定!$B$5),"{料金}",設定!$B$7),"{日付1}",設定!$B$8),"{日付2}",設定!$B$9),"{時間1}",設定!$B$10),"{時間2}",設定!$B$11),"{時間}","（指定時間）"),"{日付確定}","（確定日）"),"{時間確定}","（確定時間）")) | AG14: =IFERROR(VLOOKUP(DF14,スクリプト_フロー!$A:$F,4,FALSE),"") | CZ14: =R14&"|"&S14 -> | | DA14: =IFERROR(VLOOKUP(CZ14,スクリプト_フロー!$A:$F,5,FALSE),"") | DB14: =V14&"|"&W14 -> | | DC14: =IFERROR(VLOOKUP(DB14,スクリプト_フロー!$A:$F,5,FALSE),"") | DD14: =Z14&"|"&AA14 -> |⑫決裁者確認 | DE14: =IFERROR(VLOOKUP(DD14,スクリプト_フロー!$A:$F,5,FALSE),"") | DF14: =AD14&"|"&AE14 -> |RESPX_013 | DG14: =IFERROR(VLOOKUP(DF14,スクリプト_フロー!$A:$F,5,FALSE),"")
... A20: 19 | B20: ホテルサンバリーアネックス | C20: 0977-26-6555 | D20: 石垣・浜脇周辺 | G20: ①架電 | I20: =SUBSTITUTE(SUBSTITUTE(SUBSTITUTE(SUBSTITUTE(SUBSTITUTE(SUBSTITUTE(SUBSTITUTE(SUBSTITUTE(SUBSTITUTE(SUBSTITUTE(SUBSTITUTE(Q20,"{会社}",設定!$B$3),"{自分}",設定!$B$4),"{サービス}",設定!$B$5),"{料金}",設定!$B$7),"{日付1}",設定!$B$8),"{日付2}",設定!$B$9),"{時間1}",設定!$B$10),"{時間2}",設定!$B$11),"{時間}","（指定時間）"),"{日付確定}","（確定日）"),"{時間確定}","（確定時間）") | J20: =IFERROR(VLOOKUP(P20,スクリプト_フロー!$A:$F,4,FALSE),"") | K20: 未架電 | P20: =G20&"|"&H20 -> ①架電| | Q20: =IFERROR(VLOOKUP(P20,スクリプト_フロー!$A:$F,5,FALSE),"") | R20: =IF(J20="","",J20) | T20: =IF(DA20="","",SUBSTITUTE(SUBSTITUTE(SUBSTITUTE(SUBSTITUTE(SUBSTITUTE(SUBSTITUTE(SUBSTITUTE(SUBSTITUTE(SUBSTITUTE(SUBSTITUTE(SUBSTITUTE(DA20,"{会社}",設定!$B$3),"{自分}",設定!$B$4),"{サービス}",設定!$B$5),"{料金}",設定!$B$7),"{日付1}",設定!$B$8),"{日付2}",設定!$B$9),"{時間1}",設定!$B$10),"{時間2}",設定!$B$11),"{時間}","（指定時間）"),"{日付確定}","（確定日）"),"{時間確定}","（確定時間）")) | U20: =IFERROR(VLOOKUP(CZ20,スクリプト_フロー!$A:$F,4,FALSE),"") | V20: =IF(U20="","",U20) | X20: =IF(DC20="","",SUBSTITUTE(SUBSTITUTE(SUBSTITUTE(SUBSTITUTE(SUBSTITUTE(SUBSTITUTE(SUBSTITUTE(SUBSTITUTE(SUBSTITUTE(SUBSTITUTE(SUBSTITUTE(DC20,"{会社}",設定!$B$3),"{自分}",設定!$B$4),"{サービス}",設定!$B$5),"{料金}",設定!$B$7),"{日付1}",設定!$B$8),"{日付2}",設定!$B$9),"{時間1}",設定!$B$10),"{時間2}",設定!$B$11),"{時間}","（指定時間）"),"{日付確定}","（確定日）"),"{時間確定}","（確定時間）")) | Y20: =IFERROR(VLOOKUP(DB20,スクリプト_フロー!$A:$F,4,FALSE),"") | Z20: =IF(Y20="","",Y20) | AA20: ⑱丁寧終了 | AB20: =IF(DE20="","",SUBSTITUTE(SUBSTITUTE(SUBSTITUTE(SUBSTITUTE(SUBSTITUTE(SUBSTITUTE(SUBSTITUTE(SUBSTITUTE(SUBSTITUTE(SUBSTITUTE(SUBSTITUTE(DE20,"{会社}",設定!$B$3),"{自分}",設定!$B$4),"{サービス}",設定!$B$5),"{料金}",設定!$B$7),"{日付1}",設定!$B$8),"{日付2}",設定!$B$9),"{時間1}",設定!$B$10),"{時間2}",設定!$B$11),"{時間}","（指定時間）"),"{日付確定}","（確定日）"),"{時間確定}","（確定時間）")) | AC20: =IFERROR(VLOOKUP(DD20,スクリプト_フロー!$A:$F,4,FALSE),"") | AD20: =IF(AC20="","",AC20) | AE20: RESPX_019 | AF20: =IF(DG20="","",SUBSTITUTE(SUBSTITUTE(SUBSTITUTE(SUBSTITUTE(SUBSTITUTE(SUBSTITUTE(SUBSTITUTE(SUBSTITUTE(SUBSTITUTE(SUBSTITUTE(SUBSTITUTE(DG20,"{会社}",設定!$B$3),"{自分}",設定!$B$4),"{サービス}",設定!$B$5),"{料金}",設定!$B$7),"{日付1}",設定!$B$8),"{日付2}",設定!$B$9),"{時間1}",設定!$B$10),"{時間2}",設定!$B$11),"{時間}","（指定時間）"),"{日付確定}","（確定日）"),"{時間確定}","（確定時間）")) | AG20: =IFERROR(VLOOKUP(DF20,スクリプト_フロー!$A:$F,4,FALSE),"") | CZ20: =R20&"|"&S20 -> | | DA20: =IFERROR(VLOOKUP(CZ20,スクリプト_フロー!$A:$F,5,FALSE),"") | DB20: =V20&"|"&W20 -> | | DC20: =IFERROR(VLOOKUP(DB20,スクリプト_フロー!$A:$F,5,FALSE),"") | DD20: =Z20&"|"&AA20 -> |⑱丁寧終了 | DE20: =IFERROR(VLOOKUP(DD20,スクリプト_フロー!$A:$F,5,FALSE),"") | DF20: =AD20&"|"&AE20 -> |RESPX_019 | DG20: =IFERROR(VLOOKUP(DF20,スクリプト_フロー!$A:$F,5,FALSE),"")
A21: 20 | B21: ビジネスホテル・グッドイン別府 | C21: 0977-22-3001 | D21: 浜町・浜脇 | G21: ①架電 | I21: =SUBSTITUTE(SUBSTITUTE(SUBSTITUTE(SUBSTITUTE(SUBSTITUTE(SUBSTITUTE(SUBSTITUTE(SUBSTITUTE(SUBSTITUTE(SUBSTITUTE(SUBSTITUTE(Q21,"{会社}",設定!$B$3),"{自分}",設定!$B$4),"{サービス}",設定!$B$5),"{料金}",設定!$B$7),"{日付1}",設定!$B$8),"{日付2}",設定!$B$9),"{時間1}",設定!$B$10),"{時間2}",設定!$B$11),"{時間}","（指定時間）"),"{日付確定}","（確定日）"),"{時間確定}","（確定時間）") | J21: =IFERROR(VLOOKUP(P21,スクリプト_フロー!$A:$F,4,FALSE),"") | K21: 未架電 | P21: =G21&"|"&H21 -> ①架電| | Q21: =IFERROR(VLOOKUP(P21,スクリプト_フロー!$A:$F,5,FALSE),"") | R21: =IF(J21="","",J21) | T21: =IF(DA21="","",SUBSTITUTE(SUBSTITUTE(SUBSTITUTE(SUBSTITUTE(SUBSTITUTE(SUBSTITUTE(SUBSTITUTE(SUBSTITUTE(SUBSTITUTE(SUBSTITUTE(SUBSTITUTE(DA21,"{会社}",設定!$B$3),"{自分}",設定!$B$4),"{サービス}",設定!$B$5),"{料金}",設定!$B$7),"{日付1}",設定!$B$8),"{日付2}",設定!$B$9),"{時間1}",設定!$B$10),"{時間2}",設定!$B$11),"{時間}","（指定時間）"),"{日付確定}","（確定日）"),"{時間確定}","（確定時間）")) | U21: =IFERROR(VLOOKUP(CZ21,スクリプト_フロー!$A:$F,4,FALSE),"") | V21: =IF(U21="","",U21) | X21: =IF(DC21="","",SUBSTITUTE(SUBSTITUTE(SUBSTITUTE(SUBSTITUTE(SUBSTITUTE(SUBSTITUTE(SUBSTITUTE(SUBSTITUTE(SUBSTITUTE(SUBSTITUTE(SUBSTITUTE(DC21,"{会社}",設定!$B$3),"{自分}",設定!$B$4),"{サービス}",設定!$B$5),"{料金}",設定!$B$7),"{日付1}",設定!$B$8),"{日付2}",設定!$B$9),"{時間1}",設定!$B$10),"{時間2}",設定!$B$11),"{時間}","（指定時間）"),"{日付確定}","（確定日）"),"{時間確定}","（確定時間）")) | Y21: =IFERROR(VLOOKUP(DB21,スクリプト_フロー!$A:$F,4,FALSE),"") | Z21: =IF(Y21="","",Y21) | AB21: =IF(DE21="","",SUBSTITUTE(SUBSTITUTE(SUBSTITUTE(SUBSTITUTE(SUBSTITUTE(SUBSTITUTE(SUBSTITUTE(SUBSTITUTE(SUBSTITUTE(SUBSTITUTE(SUBSTITUTE(DE21,"{会社}",設定!$B$3),"{自分}",設定!$B$4),"{サービス}",設定!$B$5),"{料金}",設定!$B$7),"{日付1}",設定!$B$8),"{日付2}",設定!$B$9),"{時間1}",設定!$B$10),"{時間2}",設定!$B$11),"{時間}","（指定時間）"),"{日付確定}","（確定日）"),"{時間確定}","（確定時間）")) | AC21: =IFERROR(VLOOKUP(DD21,スクリプト_フロー!$A:$F,4,FALSE),"") | AD21: =IF(AC21="","",AC21) | AF21: =IF(DG21="","",SUBSTITUTE(SUBSTITUTE(SUBSTITUTE(SUBSTITUTE(SUBSTITUTE(SUBSTITUTE(SUBSTITUTE(SUBSTITUTE(SUBSTITUTE(SUBSTITUTE(SUBSTITUTE(DG21,"{会社}",設定!$B$3),"{自分}",設定!$B$4),"{サービス}",設定!$B$5),"{料金}",設定!$B$7),"{日付1}",設定!$B$8),"{日付2}",設定!$B$9),"{時間1}",設定!$B$10),"{時間2}",設定!$B$11),"{時間}","（指定時間）"),"{日付確定}","（確定日）"),"{時間確定}","（確定時間）")) | AG21: =IFERROR(VLOOKUP(DF21,スクリプト_フロー!$A:$F,4,FALSE),"") | CZ21: =R21&"|"&S21 -> | | DA21: =IFERROR(VLOOKUP(CZ21,スクリプト_フロー!$A:$F,5,FALSE),"") | DB21: =V21&"|"&W21 -> | | DC21: =IFERROR(VLOOKUP(DB21,スクリプト_フロー!$A:$F,5,FALSE),"") | DD21: =Z21&"|"&AA21 -> | | DE21: =IFERROR(VLOOKUP(DD21,スクリプト_フロー!$A:$F,5,FALSE),"") | DF21: =AD21&"|"&AE21 -> | | DG21: =IFERROR(VLOOKUP(DF21,スクリプト_フロー!$A:$F,5,FALSE),"")
A22: 21 | B22: 別府第一ホテル | C22: 0977-24-6311 | D22: 別府駅周辺 | G22: ①架電 | I22: =SUBSTITUTE(SUBSTITUTE(SUBSTITUTE(SUBSTITUTE(SUBSTITUTE(SUBSTITUTE(SUBSTITUTE(SUBSTITUTE(SUBSTITUTE(SUBSTITUTE(SUBSTITUTE(Q22,"{会社}",設定!$B$3),"{自分}",設定!$B$4),"{サービス}",設定!$B$5),"{料金}",設定!$B$7),"{日付1}",設定!$B$8),"{日付2}",設定!$B$9),"{時間1}",設定!$B$10),"{時間2}",設定!$B$11),"{時間}","（指定時間）"),"{日付確定}","（確定日）"),"{時間確定}","（確定時間）") | J22: =IFERROR(VLOOKUP(P22,スクリプト_フロー!$A:$F,4,FALSE),"") | K22: 未架電 | P22: =G22&"|"&H22 -> ①架電| | Q22: =IFERROR(VLOOKUP(P22,スクリプト_フロー!$A:$F,5,FALSE),"") | R22: =IF(J22="","",J22) | T22: =IF(DA22="","",SUBSTITUTE(SUBSTITUTE(SUBSTITUTE(SUBSTITUTE(SUBSTITUTE(SUBSTITUTE(SUBSTITUTE(SUBSTITUTE(SUBSTITUTE(SUBSTITUTE(SUBSTITUTE(DA22,"{会社}",設定!$B$3),"{自分}",設定!$B$4),"{サービス}",設定!$B$5),"{料金}",設定!$B$7),"{日付1}",設定!$B$8),"{日付2}",設定!$B$9),"{時間1}",設定!$B$10),"{時間2}",設定!$B$11),"{時間}","（指定時間）"),"{日付確定}","（確定日）"),"{時間確定}","（確定時間）")) | U22: =IFERROR(VLOOKUP(CZ22,スクリプト_フロー!$A:$F,4,FALSE),"") | V22: =IF(U22="","",U22) | X22: =IF(DC22="","",SUBSTITUTE(SUBSTITUTE(SUBSTITUTE(SUBSTITUTE(SUBSTITUTE(SUBSTITUTE(SUBSTITUTE(SUBSTITUTE(SUBSTITUTE(SUBSTITUTE(SUBSTITUTE(DC22,"{会社}",設定!$B$3),"{自分}",設定!$B$4),"{サービス}",設定!$B$5),"{料金}",設定!$B$7),"{日付1}",設定!$B$8),"{日付2}",設定!$B$9),"{時間1}",設定!$B$10),"{時間2}",設定!$B$11),"{時間}","（指定時間）"),"{日付確定}","（確定日）"),"{時間確定}","（確定時間）")) | Y22: =IFERROR(VLOOKUP(DB22,スクリプト_フロー!$A:$F,4,FALSE),"") | Z22: =IF(Y22="","",Y22) | AB22: =IF(DE22="","",SUBSTITUTE(SUBSTITUTE(SUBSTITUTE(SUBSTITUTE(SUBSTITUTE(SUBSTITUTE(SUBSTITUTE(SUBSTITUTE(SUBSTITUTE(SUBSTITUTE(SUBSTITUTE(DE22,"{会社}",設定!$B$3),"{自分}",設定!$B$4),"{サービス}",設定!$B$5),"{料金}",設定!$B$7),"{日付1}",設定!$B$8),"{日付2}",設定!$B$9),"{時間1}",設定!$B$10),"{時間2}",設定!$B$11),"{時間}","（指定時間）"),"{日付確定}","（確定日）"),"{時間確定}","（確定時間）")) | AC22: =IFERROR(VLOOKUP(DD22,スクリプト_フロー!$A:$F,4,FALSE),"") | AD22: =IF(AC22="","",AC22) | AF22: =IF(DG22="","",SUBSTITUTE(SUBSTITUTE(SUBSTITUTE(SUBSTITUTE(SUBSTITUTE(SUBSTITUTE(SUBSTITUTE(SUBSTITUTE(SUBSTITUTE(SUBSTITUTE(SUBSTITUTE(DG22,"{会社}",設定!$B$3),"{自分}",設定!$B$4),"{サービス}",設定!$B$5),"{料金}",設定!$B$7),"{日付1}",設定!$B$8),"{日付2}",設定!$B$9),"{時間1}",設定!$B$10),"{時間2}",設定!$B$11),"{時間}","（指定時間）"),"{日付確定}","（確定日）"),"{時間確定}","（確定時間）")) | AG22: =IFERROR(VLOOKUP(DF22,スクリプト_フロー!$A:$F,4,FALSE),"") | CZ22: =R22&"|"&S22 -> | | DA22: =IFERROR(VLOOKUP(CZ22,スクリプト_フロー!$A:$F,5,FALSE),"") | DB22: =V22&"|"&W22 -> | | DC22: =IFERROR(VLOOKUP(DB22,スクリプト_フロー!$A:$F,5,FALSE),"") | DD22: =Z22&"|"&AA22 -> | | DE22: =IFERROR(VLOOKUP(DD22,スクリプト_フロー!$A:$F,5,FALSE),"") | DF22: =AD22&"|"&AE22 -> | | DG22: =IFERROR(VLOOKUP(DF22,スクリプト_フロー!$A:$F,5,FALSE),"")
A23: 22 | B23: ホテルアーサー KITAHAMA BASE | C23: 0977-25-2611 | D23: 北浜 | G23: ①架電 | I23: =SUBSTITUTE(SUBSTITUTE(SUBSTITUTE(SUBSTITUTE(SUBSTITUTE(SUBSTITUTE(SUBSTITUTE(SUBSTITUTE(SUBSTITUTE(SUBSTITUTE(SUBSTITUTE(Q23,"{会社}",設定!$B$3),"{自分}",設定!$B$4),"{サービス}",設定!$B$5),"{料金}",設定!$B$7),"{日付1}",設定!$B$8),"{日付2}",設定!$B$9),"{時間1}",設定!$B$10),"{時間2}",設定!$B$11),"{時間}","（指定時間）"),"{日付確定}","（確定日）"),"{時間確定}","（確定時間）") | J23: =IFERROR(VLOOKUP(P23,スクリプト_フロー!$A:$F,4,FALSE),"") | K23: 未架電 | P23: =G23&"|"&H23 -> ①架電| | Q23: =IFERROR(VLOOKUP(P23,スクリプト_フロー!$A:$F,5,FALSE),"") | R23: =IF(J23="","",J23) | T23: =IF(DA23="","",SUBSTITUTE(SUBSTITUTE(SUBSTITUTE(SUBSTITUTE(SUBSTITUTE(SUBSTITUTE(SUBSTITUTE(SUBSTITUTE(SUBSTITUTE(SUBSTITUTE(SUBSTITUTE(DA23,"{会社}",設定!$B$3),"{自分}",設定!$B$4),"{サービス}",設定!$B$5),"{料金}",設定!$B$7),"{日付1}",設定!$B$8),"{日付2}",設定!$B$9),"{時間1}",設定!$B$10),"{時間2}",設定!$B$11),"{時間}","（指定時間）"),"{日付確定}","（確定日）"),"{時間確定}","（確定時間）")) | U23: =IFERROR(VLOOKUP(CZ23,スクリプト_フロー!$A:$F,4,FALSE),"") | V23: =IF(U23="","",U23) | X23: =IF(DC23="","",SUBSTITUTE(SUBSTITUTE(SUBSTITUTE(SUBSTITUTE(SUBSTITUTE(SUBSTITUTE(SUBSTITUTE(SUBSTITUTE(SUBSTITUTE(SUBSTITUTE(SUBSTITUTE(DC23,"{会社}",設定!$B$3),"{自分}",設定!$B$4),"{サービス}",設定!$B$5),"{料金}",設定!$B$7),"{日付1}",設定!$B$8),"{日付2}",設定!$B$9),"{時間1}",設定!$B$10),"{時間2}",設定!$B$11),"{時間}","（指定時間）"),"{日付確定}","（確定日）"),"{時間確定}","（確定時間）")) | Y23: =IFERROR(VLOOKUP(DB23,スクリプト_フロー!$A:$F,4,FALSE),"") | Z23: =IF(Y23="","",Y23) | AB23: =IF(DE23="","",SUBSTITUTE(SUBSTITUTE(SUBSTITUTE(SUBSTITUTE(SUBSTITUTE(SUBSTITUTE(SUBSTITUTE(SUBSTITUTE(SUBSTITUTE(SUBSTITUTE(SUBSTITUTE(DE23,"{会社}",設定!$B$3),"{自分}",設定!$B$4),"{サービス}",設定!$B$5),"{料金}",設定!$B$7),"{日付1}",設定!$B$8),"{日付2}",設定!$B$9),"{時間1}",設定!$B$10),"{時間2}",設定!$B$11),"{時間}","（指定時間）"),"{日付確定}","（確定日）"),"{時間確定}","（確定時間）")) | AC23: =IFERROR(VLOOKUP(DD23,スクリプト_フロー!$A:$F,4,FALSE),"") | AD23: =IF(AC23="","",AC23) | AF23: =IF(DG23="","",SUBSTITUTE(SUBSTITUTE(SUBSTITUTE(SUBSTITUTE(SUBSTITUTE(SUBSTITUTE(SUBSTITUTE(SUBSTITUTE(SUBSTITUTE(SUBSTITUTE(SUBSTITUTE(DG23,"{会社}",設定!$B$3),"{自分}",設定!$B$4),"{サービス}",設定!$B$5),"{料金}",設定!$B$7),"{日付1}",設定!$B$8),"{日付2}",設定!$B$9),"{時間1}",設定!$B$10),"{時間2}",設定!$B$11),"{時間}","（指定時間）"),"{日付確定}","（確定日）"),"{時間確定}","（確定時間）")) | AG23: =IFERROR(VLOOKUP(DF23,スクリプト_フロー!$A:$F,4,FALSE),"") | CZ23: =R23&"|"&S23 -> | | DA23: =IFERROR(VLOOKUP(CZ23,スクリプト_フロー!$A:$F,5,FALSE),"") | DB23: =V23&"|"&W23 -> | | DC23: =IFERROR(VLOOKUP(DB23,スクリプト_フロー!$A:$F,5,FALSE),"") | DD23: =Z23&"|"&AA23 -> | | DE23: =IFERROR(VLOOKUP(DD23,スクリプト_フロー!$A:$F,5,FALSE),"") | DF23: =AD23&"|"&AE23 -> | | DG23: =IFERROR(VLOOKUP(DF23,スクリプト_フロー!$A:$F,5,FALSE),"")
A24: 23 | B24: 別府ホテルエール（HOTEL AILE） | C24: 0977-21-7272 | D24: 北浜 | G24: ①架電 | I24: =SUBSTITUTE(SUBSTITUTE(SUBSTITUTE(SUBSTITUTE(SUBSTITUTE(SUBSTITUTE(SUBSTITUTE(SUBSTITUTE(SUBSTITUTE(SUBSTITUTE(SUBSTITUTE(Q24,"{会社}",設定!$B$3),"{自分}",設定!$B$4),"{サービス}",設定!$B$5),"{料金}",設定!$B$7),"{日付1}",設定!$B$8),"{日付2}",設定!$B$9),"{時間1}",設定!$B$10),"{時間2}",設定!$B$11),"{時間}","（指定時間）"),"{日付確定}","（確定日）"),"{時間確定}","（確定時間）") | J24: =IFERROR(VLOOKUP(P24,スクリプト_フロー!$A:$F,4,FALSE),"") | K24: 未架電 | P24: =G24&"|"&H24 -> ①架電| | Q24: =IFERROR(VLOOKUP(P24,スクリプト_フロー!$A:$F,5,FALSE),"") | R24: =IF(J24="","",J24) | T24: =IF(DA24="","",SUBSTITUTE(SUBSTITUTE(SUBSTITUTE(SUBSTITUTE(SUBSTITUTE(SUBSTITUTE(SUBSTITUTE(SUBSTITUTE(SUBSTITUTE(SUBSTITUTE(SUBSTITUTE(DA24,"{会社}",設定!$B$3),"{自分}",設定!$B$4),"{サービス}",設定!$B$5),"{料金}",設定!$B$7),"{日付1}",設定!$B$8),"{日付2}",設定!$B$9),"{時間1}",設定!$B$10),"{時間2}",設定!$B$11),"{時間}","（指定時間）"),"{日付確定}","（確定日）"),"{時間確定}","（確定時間）")) | U24: =IFERROR(VLOOKUP(CZ24,スクリプト_フロー!$A:$F,4,FALSE),"") | V24: =IF(U24="","",U24) | X24: =IF(DC24="","",SUBSTITUTE(SUBSTITUTE(SUBSTITUTE(SUBSTITUTE(SUBSTITUTE(SUBSTITUTE(SUBSTITUTE(SUBSTITUTE(SUBSTITUTE(SUBSTITUTE(SUBSTITUTE(DC24,"{会社}",設定!$B$3),"{自分}",設定!$B$4),"{サービス}",設定!$B$5),"{料金}",設定!$B$7),"{日付1}",設定!$B$8),"{日付2}",設定!$B$9),"{時間1}",設定!$B$10),"{時間2}",設定!$B$11),"{時間}","（指定時間）"),"{日付確定}","（確定日）"),"{時間確定}","（確定時間）")) | Y24: =IFERROR(VLOOKUP(DB24,スクリプト_フロー!$A:$F,4,FALSE),"") | Z24: =IF(Y24="","",Y24) | AB24: =IF(DE24="","",SUBSTITUTE(SUBSTITUTE(SUBSTITUTE(SUBSTITUTE(SUBSTITUTE(SUBSTITUTE(SUBSTITUTE(SUBSTITUTE(SUBSTITUTE(SUBSTITUTE(SUBSTITUTE(DE24,"{会社}",設定!$B$3),"{自分}",設定!$B$4),"{サービス}",設定!$B$5),"{料金}",設定!$B$7),"{日付1}",設定!$B$8),"{日付2}",設定!$B$9),"{時間1}",設定!$B$10),"{時間2}",設定!$B$11),"{時間}","（指定時間）"),"{日付確定}","（確定日）"),"{時間確定}","（確定時間）")) | AC24: =IFERROR(VLOOKUP(DD24,スクリプト_フロー!$A:$F,4,FALSE),"") | AD24: =IF(AC24="","",AC24) | AF24: =IF(DG24="","",SUBSTITUTE(SUBSTITUTE(SUBSTITUTE(SUBSTITUTE(SUBSTITUTE(SUBSTITUTE(SUBSTITUTE(SUBSTITUTE(SUBSTITUTE(SUBSTITUTE(SUBSTITUTE(DG24,"{会社}",設定!$B$3),"{自分}",設定!$B$4),"{サービス}",設定!$B$5),"{料金}",設定!$B$7),"{日付1}",設定!$B$8),"{日付2}",設定!$B$9),"{時間1}",設定!$B$10),"{時間2}",設定!$B$11),"{時間}","（指定時間）"),"{日付確定}","（確定日）"),"{時間確定}","（確定時間）")) | AG24: =IFERROR(VLOOKUP(DF24,スクリプト_フロー!$A:$F,4,FALSE),"") | CZ24: =R24&"|"&S24 -> | | DA24: =IFERROR(VLOOKUP(CZ24,スクリプト_フロー!$A:$F,5,FALSE),"") | DB24: =V24&"|"&W24 -> | | DC24: =IFERROR(VLOOKUP(DB24,スクリプト_フロー!$A:$F,5,FALSE),"") | DD24: =Z24&"|"&AA24 -> | | DE24: =IFERROR(VLOOKUP(DD24,スクリプト_フロー!$A:$F,5,FALSE),"") | DF24: =AD24&"|"&AE24 -> | | DG24: =IFERROR(VLOOKUP(DF24,スクリプト_フロー!$A:$F,5,FALSE),"")
A25: 24 | B25: ホテルなぎさ | C25: 0977-23-8101 | D25: 北浜 | G25: ①架電 | I25: =SUBSTITUTE(SUBSTITUTE(SUBSTITUTE(SUBSTITUTE(SUBSTITUTE(SUBSTITUTE(SUBSTITUTE(SUBSTITUTE(SUBSTITUTE(SUBSTITUTE(SUBSTITUTE(Q25,"{会社}",設定!$B$3),"{自分}",設定!$B$4),"{サービス}",設定!$B$5),"{料金}",設定!$B$7),"{日付1}",設定!$B$8),"{日付2}",設定!$B$9),"{時間1}",設定!$B$10),"{時間2}",設定!$B$11),"{時間}","（指定時間）"),"{日付確定}","（確定日）"),"{時間確定}","（確定時間）") | J25: =IFERROR(VLOOKUP(P25,スクリプト_フロー!$A:$F,4,FALSE),"") | K25: 未架電 | P25: =G25&"|"&H25 -> ①架電| | Q25: =IFERROR(VLOOKUP(P25,スクリプト_フロー!$A:$F,5,FALSE),"") | R25: =IF(J25="","",J25) | T25: =IF(DA25="","",SUBSTITUTE(SUBSTITUTE(SUBSTITUTE(SUBSTITUTE(SUBSTITUTE(SUBSTITUTE(SUBSTITUTE(SUBSTITUTE(SUBSTITUTE(SUBSTITUTE(SUBSTITUTE(DA25,"{会社}",設定!$B$3),"{自分}",設定!$B$4),"{サービス}",設定!$B$5),"{料金}",設定!$B$7),"{日付1}",設定!$B$8),"{日付2}",設定!$B$9),"{時間1}",設定!$B$10),"{時間2}",設定!$B$11),"{時間}","（指定時間）"),"{日付確定}","（確定日）"),"{時間確定}","（確定時間）")) | U25: =IFERROR(VLOOKUP(CZ25,スクリプト_フロー!$A:$F,4,FALSE),"") | V25: =IF(U25="","",U25) | X25: =IF(DC25="","",SUBSTITUTE(SUBSTITUTE(SUBSTITUTE(SUBSTITUTE(SUBSTITUTE(SUBSTITUTE(SUBSTITUTE(SUBSTITUTE(SUBSTITUTE(SUBSTITUTE(SUBSTITUTE(DC25,"{会社}",設定!$B$3),"{自分}",設定!$B$4),"{サービス}",設定!$B$5),"{料金}",設定!$B$7),"{日付1}",設定!$B$8),"{日付2}",設定!$B$9),"{時間1}",設定!$B$10),"{時間2}",設定!$B$11),"{時間}","（指定時間）"),"{日付確定}","（確定日）"),"{時間確定}","（確定時間）")) | Y25: =IFERROR(VLOOKUP(DB25,スクリプト_フロー!$A:$F,4,FALSE),"") | Z25: =IF(Y25="","",Y25) | AB25: =IF(DE25="","",SUBSTITUTE(SUBSTITUTE(SUBSTITUTE(SUBSTITUTE(SUBSTITUTE(SUBSTITUTE(SUBSTITUTE(SUBSTITUTE(SUBSTITUTE(SUBSTITUTE(SUBSTITUTE(DE25,"{会社}",設定!$B$3),"{自分}",設定!$B$4),"{サービス}",設定!$B$5),"{料金}",設定!$B$7),"{日付1}",設定!$B$8),"{日付2}",設定!$B$9),"{時間1}",設定!$B$10),"{時間2}",設定!$B$11),"{時間}","（指定時間）"),"{日付確定}","（確定日）"),"{時間確定}","（確定時間）")) | AC25: =IFERROR(VLOOKUP(DD25,スクリプト_フロー!$A:$F,4,FALSE),"") | AD25: =IF(AC25="","",AC25) | AF25: =IF(DG25="","",SUBSTITUTE(SUBSTITUTE(SUBSTITUTE(SUBSTITUTE(SUBSTITUTE(SUBSTITUTE(SUBSTITUTE(SUBSTITUTE(SUBSTITUTE(SUBSTITUTE(SUBSTITUTE(DG25,"{会社}",設定!$B$3),"{自分}",設定!$B$4),"{サービス}",設定!$B$5),"{料金}",設定!$B$7),"{日付1}",設定!$B$8),"{日付2}",設定!$B$9),"{時間1}",設定!$B$10),"{時間2}",設定!$B$11),"{時間}","（指定時間）"),"{日付確定}","（確定日）"),"{時間確定}","（確定時間）")) | AG25: =IFERROR(VLOOKUP(DF25,スクリプト_フロー!$A:$F,4,FALSE),"") | CZ25: =R25&"|"&S25 -> | | DA25: =IFERROR(VLOOKUP(CZ25,スクリプト_フロー!$A:$F,5,FALSE),"") | DB25: =V25&"|"&W25 -> | | DC25: =IFERROR(VLOOKUP(DB25,スクリプト_フロー!$A:$F,5,FALSE),"") | DD25: =Z25&"|"&AA25 -> | | DE25: =IFERROR(VLOOKUP(DD25,スクリプト_フロー!$A:$F,5,FALSE),"") | DF25: =AD25&"|"&AE25 -> | | DG25: =IFERROR(VLOOKUP(DF25,スクリプト_フロー!$A:$F,5,FALSE),"")
A26: 25 | B26: ジェイホッパーズ別府ゲストハウス | C26: 0977-26-1700 | D26: 的ヶ浜 | G26: ①架電 | I26: =SUBSTITUTE(SUBSTITUTE(SUBSTITUTE(SUBSTITUTE(SUBSTITUTE(SUBSTITUTE(SUBSTITUTE(SUBSTITUTE(SUBSTITUTE(SUBSTITUTE(SUBSTITUTE(Q26,"{会社}",設定!$B$3),"{自分}",設定!$B$4),"{サービス}",設定!$B$5),"{料金}",設定!$B$7),"{日付1}",設定!$B$8),"{日付2}",設定!$B$9),"{時間1}",設定!$B$10),"{時間2}",設定!$B$11),"{時間}","（指定時間）"),"{日付確定}","（確定日）"),"{時間確定}","（確定時間）") | J26: =IFERROR(VLOOKUP(P26,スクリプト_フロー!$A:$F,4,FALSE),"") | K26: 未架電 | P26: =G26&"|"&H26 -> ①架電| | Q26: =IFERROR(VLOOKUP(P26,スクリプト_フロー!$A:$F,5,FALSE),"") | R26: =IF(J26="","",J26) | T26: =IF(DA26="","",SUBSTITUTE(SUBSTITUTE(SUBSTITUTE(SUBSTITUTE(SUBSTITUTE(SUBSTITUTE(SUBSTITUTE(SUBSTITUTE(SUBSTITUTE(SUBSTITUTE(SUBSTITUTE(DA26,"{会社}",設定!$B$3),"{自分}",設定!$B$4),"{サービス}",設定!$B$5),"{料金}",設定!$B$7),"{日付1}",設定!$B$8),"{日付2}",設定!$B$9),"{時間1}",設定!$B$10),"{時間2}",設定!$B$11),"{時間}","（指定時間）"),"{日付確定}","（確定日）"),"{時間確定}","（確定時間）")) | U26: =IFERROR(VLOOKUP(CZ26,スクリプト_フロー!$A:$F,4,FALSE),"") | V26: =IF(U26="","",U26) | X26: =IF(DC26="","",SUBSTITUTE(SUBSTITUTE(SUBSTITUTE(SUBSTITUTE(SUBSTITUTE(SUBSTITUTE(SUBSTITUTE(SUBSTITUTE(SUBSTITUTE(SUBSTITUTE(SUBSTITUTE(DC26,"{会社}",設定!$B$3),"{自分}",設定!$B$4),"{サービス}",設定!$B$5),"{料金}",設定!$B$7),"{日付1}",設定!$B$8),"{日付2}",設定!$B$9),"{時間1}",設定!$B$10),"{時間2}",設定!$B$11),"{時間}","（指定時間）"),"{日付確定}","（確定日）"),"{時間確定}","（確定時間）")) | Y26: =IFERROR(VLOOKUP(DB26,スクリプト_フロー!$A:$F,4,FALSE),"") | Z26: =IF(Y26="","",Y26) | AB26: =IF(DE26="","",SUBSTITUTE(SUBSTITUTE(SUBSTITUTE(SUBSTITUTE(SUBSTITUTE(SUBSTITUTE(SUBSTITUTE(SUBSTITUTE(SUBSTITUTE(SUBSTITUTE(SUBSTITUTE(DE26,"{会社}",設定!$B$3),"{自分}",設定!$B$4),"{サービス}",設定!$B$5),"{料金}",設定!$B$7),"{日付1}",設定!$B$8),"{日付2}",設定!$B$9),"{時間1}",設定!$B$10),"{時間2}",設定!$B$11),"{時間}","（指定時間）"),"{日付確定}","（確定日）"),"{時間確定}","（確定時間）")) | AC26: =IFERROR(VLOOKUP(DD26,スクリプト_フロー!$A:$F,4,FALSE),"") | AD26: =IF(AC26="","",AC26) | AF26: =IF(DG26="","",SUBSTITUTE(SUBSTITUTE(SUBSTITUTE(SUBSTITUTE(SUBSTITUTE(SUBSTITUTE(SUBSTITUTE(SUBSTITUTE(SUBSTITUTE(SUBSTITUTE(SUBSTITUTE(DG26,"{会社}",設定!$B$3),"{自分}",設定!$B$4),"{サービス}",設定!$B$5),"{料金}",設定!$B$7),"{日付1}",設定!$B$8),"{日付2}",設定!$B$9),"{時間1}",設定!$B$10),"{時間2}",設定!$B$11),"{時間}","（指定時間）"),"{日付確定}","（確定日）"),"{時間確定}","（確定時間）")) | AG26: =IFERROR(VLOOKUP(DF26,スクリプト_フロー!$A:$F,4,FALSE),"") | CZ26: =R26&"|"&S26 -> | | DA26: =IFERROR(VLOOKUP(CZ26,スクリプト_フロー!$A:$F,5,FALSE),"") | DB26: =V26&"|"&W26 -> | | DC26: =IFERROR(VLOOKUP(DB26,スクリプト_フロー!$A:$F,5,FALSE),"") | DD26: =Z26&"|"&AA26 -> | | DE26: =IFERROR(VLOOKUP(DD26,スクリプト_フロー!$A:$F,5,FALSE),"") | DF26: =AD26&"|"&AE26 -> | | DG26: =IFERROR(VLOOKUP(DF26,スクリプト_フロー!$A:$F,5,FALSE),"")
A27: 26 | B27: ホテルニューツルタ | C27: 0977-22-1110 | D27: 北浜 | G27: ①架電 | I27: =SUBSTITUTE(SUBSTITUTE(SUBSTITUTE(SUBSTITUTE(SUBSTITUTE(SUBSTITUTE(SUBSTITUTE(SUBSTITUTE(SUBSTITUTE(SUBSTITUTE(SUBSTITUTE(Q27,"{会社}",設定!$B$3),"{自分}",設定!$B$4),"{サービス}",設定!$B$5),"{料金}",設定!$B$7),"{日付1}",設定!$B$8),"{日付2}",設定!$B$9),"{時間1}",設定!$B$10),"{時間2}",設定!$B$11),"{時間}","（指定時間）"),"{日付確定}","（確定日）"),"{時間確定}","（確定時間）") | J27: =IFERROR(VLOOKUP(P27,スクリプト_フロー!$A:$F,4,FALSE),"") | K27: 未架電 | P27: =G27&"|"&H27 -> ①架電| | Q27: =IFERROR(VLOOKUP(P27,スクリプト_フロー!$A:$F,5,FALSE),"") | R27: =IF(J27="","",J27) | T27: =IF(DA27="","",SUBSTITUTE(SUBSTITUTE(SUBSTITUTE(SUBSTITUTE(SUBSTITUTE(SUBSTITUTE(SUBSTITUTE(SUBSTITUTE(SUBSTITUTE(SUBSTITUTE(SUBSTITUTE(DA27,"{会社}",設定!$B$3),"{自分}",設定!$B$4),"{サービス}",設定!$B$5),"{料金}",設定!$B$7),"{日付1}",設定!$B$8),"{日付2}",設定!$B$9),"{時間1}",設定!$B$10),"{時間2}",設定!$B$11),"{時間}","（指定時間）"),"{日付確定}","（確定日）"),"{時間確定}","（確定時間）")) | U27: =IFERROR(VLOOKUP(CZ27,スクリプト_フロー!$A:$F,4,FALSE),"") | V27: =IF(U27="","",U27) | X27: =IF(DC27="","",SUBSTITUTE(SUBSTITUTE(SUBSTITUTE(SUBSTITUTE(SUBSTITUTE(SUBSTITUTE(SUBSTITUTE(SUBSTITUTE(SUBSTITUTE(SUBSTITUTE(SUBSTITUTE(DC27,"{会社}",設定!$B$3),"{自分}",設定!$B$4),"{サービス}",設定!$B$5),"{料金}",設定!$B$7),"{日付1}",設定!$B$8),"{日付2}",設定!$B$9),"{時間1}",設定!$B$10),"{時間2}",設定!$B$11),"{時間}","（指定時間）"),"{日付確定}","（確定日）"),"{時間確定}","（確定時間）")) | Y27: =IFERROR(VLOOKUP(DB27,スクリプト_フロー!$A:$F,4,FALSE),"") | Z27: =IF(Y27="","",Y27) | AB27: =IF(DE27="","",SUBSTITUTE(SUBSTITUTE(SUBSTITUTE(SUBSTITUTE(SUBSTITUTE(SUBSTITUTE(SUBSTITUTE(SUBSTITUTE(SUBSTITUTE(SUBSTITUTE(SUBSTITUTE(DE27,"{会社}",設定!$B$3),"{自分}",設定!$B$4),"{サービス}",設定!$B$5),"{料金}",設定!$B$7),"{日付1}",設定!$B$8),"{日付2}",設定!$B$9),"{時間1}",設定!$B$10),"{時間2}",設定!$B$11),"{時間}","（指定時間）"),"{日付確定}","（確定日）"),"{時間確定}","（確定時間）")) | AC27: =IFERROR(VLOOKUP(DD27,スクリプト_フロー!$A:$F,4,FALSE),"") | AD27: =IF(AC27="","",AC27) | AF27: =IF(DG27="","",SUBSTITUTE(SUBSTITUTE(SUBSTITUTE(SUBSTITUTE(SUBSTITUTE(SUBSTITUTE(SUBSTITUTE(SUBSTITUTE(SUBSTITUTE(SUBSTITUTE(SUBSTITUTE(DG27,"{会社}",設定!$B$3),"{自分}",設定!$B$4),"{サービス}",設定!$B$5),"{料金}",設定!$B$7),"{日付1}",設定!$B$8),"{日付2}",設定!$B$9),"{時間1}",設定!$B$10),"{時間2}",設定!$B$11),"{時間}","（指定時間）"),"{日付確定}","（確定日）"),"{時間確定}","（確定時間）")) | AG27: =IFERROR(VLOOKUP(DF27,スクリプト_フロー!$A:$F,4,FALSE),"") | CZ27: =R27&"|"&S27 -> | | DA27: =IFERROR(VLOOKUP(CZ27,スクリプト_フロー!$A:$F,5,FALSE),"") | DB27: =V27&"|"&W27 -> | | DC27: =IFERROR(VLOOKUP(DB27,スクリプト_フロー!$A:$F,5,FALSE),"") | DD27: =Z27&"|"&AA27 -> | | DE27: =IFERROR(VLOOKUP(DD27,スクリプト_フロー!$A:$F,5,FALSE),"") | DF27: =AD27&"|"&AE27 -> | | DG27: =IFERROR(VLOOKUP(DF27,スクリプト_フロー!$A:$F,5,FALSE),"")
A28: 27 | B28: 別府温泉 海乃ホテルはじめ（旧ホテルニュー松実） | C28: 0977-23-2201 | D28: 北浜 | G28: ①架電 | I28: =SUBSTITUTE(SUBSTITUTE(SUBSTITUTE(SUBSTITUTE(SUBSTITUTE(SUBSTITUTE(SUBSTITUTE(SUBSTITUTE(SUBSTITUTE(SUBSTITUTE(SUBSTITUTE(Q28,"{会社}",設定!$B$3),"{自分}",設定!$B$4),"{サービス}",設定!$B$5),"{料金}",設定!$B$7),"{日付1}",設定!$B$8),"{日付2}",設定!$B$9),"{時間1}",設定!$B$10),"{時間2}",設定!$B$11),"{時間}","（指定時間）"),"{日付確定}","（確定日）"),"{時間確定}","（確定時間）") | J28: =IFERROR(VLOOKUP(P28,スクリプト_フロー!$A:$F,4,FALSE),"") | K28: 未架電 | P28: =G28&"|"&H28 -> ①架電| | Q28: =IFERROR(VLOOKUP(P28,スクリプト_フロー!$A:$F,5,FALSE),"") | R28: =IF(J28="","",J28) | T28: =IF(DA28="","",SUBSTITUTE(SUBSTITUTE(SUBSTITUTE(SUBSTITUTE(SUBSTITUTE(SUBSTITUTE(SUBSTITUTE(SUBSTITUTE(SUBSTITUTE(SUBSTITUTE(SUBSTITUTE(DA28,"{会社}",設定!$B$3),"{自分}",設定!$B$4),"{サービス}",設定!$B$5),"{料金}",設定!$B$7),"{日付1}",設定!$B$8),"{日付2}",設定!$B$9),"{時間1}",設定!$B$10),"{時間2}",設定!$B$11),"{時間}","（指定時間）"),"{日付確定}","（確定日）"),"{時間確定}","（確定時間）")) | U28: =IFERROR(VLOOKUP(CZ28,スクリプト_フロー!$A:$F,4,FALSE),"") | V28: =IF(U28="","",U28) | X28: =IF(DC28="","",SUBSTITUTE(SUBSTITUTE(SUBSTITUTE(SUBSTITUTE(SUBSTITUTE(SUBSTITUTE(SUBSTITUTE(SUBSTITUTE(SUBSTITUTE(SUBSTITUTE(SUBSTITUTE(DC28,"{会社}",設定!$B$3),"{自分}",設定!$B$4),"{サービス}",設定!$B$5),"{料金}",設定!$B$7),"{日付1}",設定!$B$8),"{日付2}",設定!$B$9),"{時間1}",設定!$B$10),"{時間2}",設定!$B$11),"{時間}","（指定時間）"),"{日付確定}","（確定日）"),"{時間確定}","（確定時間）")) | Y28: =IFERROR(VLOOKUP(DB28,スクリプト_フロー!$A:$F,4,FALSE),"") | Z28: =IF(Y28="","",Y28) | AB28: =IF(DE28="","",SUBSTITUTE(SUBSTITUTE(SUBSTITUTE(SUBSTITUTE(SUBSTITUTE(SUBSTITUTE(SUBSTITUTE(SUBSTITUTE(SUBSTITUTE(SUBSTITUTE(SUBSTITUTE(DE28,"{会社}",設定!$B$3),"{自分}",設定!$B$4),"{サービス}",設定!$B$5),"{料金}",設定!$B$7),"{日付1}",設定!$B$8),"{日付2}",設定!$B$9),"{時間1}",設定!$B$10),"{時間2}",設定!$B$11),"{時間}","（指定時間）"),"{日付確定}","（確定日）"),"{時間確定}","（確定時間）")) | AC28: =IFERROR(VLOOKUP(DD28,スクリプト_フロー!$A:$F,4,FALSE),"") | AD28: =IF(AC28="","",AC28) | AF28: =IF(DG28="","",SUBSTITUTE(SUBSTITUTE(SUBSTITUTE(SUBSTITUTE(SUBSTITUTE(SUBSTITUTE(SUBSTITUTE(SUBSTITUTE(SUBSTITUTE(SUBSTITUTE(SUBSTITUTE(DG28,"{会社}",設定!$B$3),"{自分}",設定!$B$4),"{サービス}",設定!$B$5),"{料金}",設定!$B$7),"{日付1}",設定!$B$8),"{日付2}",設定!$B$9),"{時間1}",設定!$B$10),"{時間2}",設定!$B$11),"{時間}","（指定時間）"),"{日付確定}","（確定日）"),"{時間確定}","（確定時間）")) | AG28: =IFERROR(VLOOKUP(DF28,スクリプト_フロー!$A:$F,4,FALSE),"") | CZ28: =R28&"|"&S28 -> | | DA28: =IFERROR(VLOOKUP(CZ28,スクリプト_フロー!$A:$F,5,FALSE),"") | DB28: =V28&"|"&W28 -> | | DC28: =IFERROR(VLOOKUP(DB28,スクリプト_フロー!$A:$F,5,FALSE),"") | DD28: =Z28&"|"&AA28 -> | | DE28: =IFERROR(VLOOKUP(DD28,スクリプト_フロー!$A:$F,5,FALSE),"") | DF28: =AD28&"|"&AE28 -> | | DG28: =IFERROR(VLOOKUP(DF28,スクリプト_フロー!$A:$F,5,FALSE),"")
